Workbook

Sheet ReadMe
A2: Ce fichier permet de construire des données marché à partir de données ICV de production pour l'aluminium
A3: Il fournit le pourcentage de chaque données ICV d'arrière plan à prendre en compte pour construire la données ICV recherchée.
A4: Les indicateurs d'impacts des données d'arrière plan ne peuvent être fournies pour des raisons de licence (base de données Ecoinvent).
A5: Pour cette raison, les indicateurs d'impacts des données construite sont à zero. Elles sont complétées automatiquement si les données d'arrière plan sont fournies.
A7: Onglet | B7: Description
A8: Résultat | B8: Construction du mix marché par pays. Calcul des émissions et Cout Environnemental, selon les données d'Arrière plan complétées
A9: Données ArrièrePlan | B9: Données ICV de production, à compléter
A10: Autoconsommation | B10: Synthèse par pays analysé des quantités d'autoconsommation, y compris recyclage
A11: Import | B11: Synthèse par pays analysé des quantités importées
A12: Correspondance Pays | B12: Table de correspondance pays Analyse / Conpens8 / Ecoinvent
A13: compens8-Prod | B13: Table de données de production, pays par pays (compens8)
A14: compens8-Import | B14: Table de données d'importation, pays par pays (compens8)
A15: compens8-Prod | B15: Table de données d'exportation, pays par pays (compens8) (utiliser pour calculer des imports nets
A17: Auteurs :
A18: - Analyse et calcul de données GES : ADEME - STM (Caroline MIR, Laurent Gagnepain)
A19: - Refonte du fichier pour diffusion libre, intégration de données de Coût Environnemental : Ecobalyse (Nicolas Planchenault)
A20: - Données Production, Import et Export (onglets dédiés) : COMPENS8 (Clément Bonnault, Nancy, compens-8.com), basé sur des données 2022
A21: - Données Taux de recyclage (colonnes Colonne L, M et O de l'onglet "autoconsommation") : COMPENS8 (Clément Bonnault, Nancy, compens-8.com), basé sur des données 2022

Sheet Résultats
C1: Mix Pays (Primaire + secondaire) | Q1: Mix vierge (Primaire seul)
A2: Pays producteur de VE | B2: Origine | C2: Impact | D2: Scrap RER | E2: Scrap RoW | F2: Amérique du Nord | G2: Chine | H2: Afrique | I2: Asie hors Chine et pays du Golfe persique | J2: Europe | K2: Pays du Golfe Persique | L2: Russie | M2: Océanie | N2: Amérique du sud | O2: Reste du monde | Q2: Impact | R2: Amérique du Nord | S2: Chine | T2: Afrique | U2: Asie hors Chine et pays du Golfe persique | V2: Europe | W2: Pays du Golfe Persique | X2: Russie | Y2: Océanie | Z2: Amérique du sud | AA2: Reste du monde | AC2: % Scrap | AD2: RER | AE2: RoW | AG2: % Autoconso | AH2: Amérique du Nord | AI2: Chine | AJ2: Afrique | AK2: Asie hors Chine et pays du Golfe persique | AL2: Europe | AM2: Pays du Golfe Persique | AN2: Russie | AO2: Océanie | AP2: Amérique du sud | AQ2: Reste du monde | AS2: % Import | AT2: Amérique du Nord | AU2: Chine | AV2: Afrique | AW2: Asie hors Chine et pays du Golfe persique | AX2: Europe | AY2: Pays du Golfe Persique | AZ2: Russie | BA2: Océanie | BB2: Amérique du sud | BC2: Reste du monde
A3: Germany | B3: Europe | C3: =SUMPRODUCT('Données ArrièrePlan'!$B$3:$M$3,$D3:$O3) -> 0 | D3: =$AC3*AD3 -> 0.41933247 | E3: =$AC3*AE3 -> 0 | F3: =$AG3*AH3+$AS3*AT3 -> 0.0050913231 | G3: =$AG3*AI3+$AS3*AU3 -> 0 | H3: =$AG3*AJ3+$AS3*AV3 -> 0.022005263 | I3: =$AG3*AK3+$AS3*AW3 -> 0.014121509 | J3: =$AG3*AL3+$AS3*AX3 -> 0.44189803 | K3: =$AG3*AM3+$AS3*AY3 -> 0.057799057 | L3: =$AG3*AN3+$AS3*AZ3 -> 0.02967239 | M3: =$AG3*AO3+$AS3*BA3 -> 0 | ... O3: =$AG3*AQ3+$AS3*BC3 -> 0.01007996 | Q3: =SUMPRODUCT('Données ArrièrePlan'!$D$3:$M$3,$R3:$AA3) -> 0 | R3: =($AG3*AH3+$AS3*AT3)/($AS3+$AG3) -> 0.008768052 | S3: =($AG3*AI3+$AS3*AU3)/($AS3+$AG3) -> 0 | T3: =($AG3*AJ3+$AS3*AV3)/($AS3+$AG3) -> 0.037896492 | U3: =($AG3*AK3+$AS3*AW3)/($AS3+$AG3) -> 0.024319439 | V3: =($AG3*AL3+$AS3*AX3)/($AS3+$AG3) -> 0.76101729 | W3: =($AG3*AM3+$AS3*AY3)/($AS3+$AG3) -> 0.099538985 | X3: =($AG3*AN3+$AS3*AZ3)/($AS3+$AG3) -> 0.051100481 | Y3: =($AG3*AO3+$AS3*BA3)/($AS3+$AG3) -> 0 | ... AA3: =($AG3*AQ3+$AS3*BC3)/($AS3+$AG3) -> 0.017359262 | AC3: =(AutoConsommation!M3+AutoConsommation!O3)/SUM(AutoConsommation!$I3,AutoConsommation!$J3,AutoConsommation!$M3,AutoConsommation!$O3) -> 0.41933247 | AD3: =IF(_xlfn.XLOOKUP($A3,AutoConsommation!$B:$B,AutoConsommation!$A:$A)=Résultats!AD$2,1,0) -> 1 | AE3: =IF(_xlfn.XLOOKUP($A3,AutoConsommation!$B:$B,AutoConsommation!$A:$A)=Résultats!AE$2,1,0) -> 0 | AG3: =(AutoConsommation!I3)/SUM(AutoConsommation!$I3,AutoConsommation!$J3,AutoConsommation!$M3,AutoConsommation!$O3) -> 0.086566239 | AH3: =IF(_xlfn.XLOOKUP($A3,'Correspondances pays'!$A$4:$A$205,'Correspondances pays'!$C$4:$C$205)=Résultats!AH$2,1,0) -> 0 | AI3: =IF(_xlfn.XLOOKUP($A3,'Correspondances pays'!$A$4:$A$205,'Correspondances pays'!$C$4:$C$205)=Résultats!AI$2,1,0) -> 0 | AJ3: =IF(_xlfn.XLOOKUP($A3,'Correspondances pays'!$A$4:$A$205,'Correspondances pays'!$C$4:$C$205)=Résultats!AJ$2,1,0) -> 0 | AK3: =IF(_xlfn.XLOOKUP($A3,'Correspondances pays'!$A$4:$A$205,'Correspondances pays'!$C$4:$C$205)=Résultats!AK$2,1,0) -> 0 | AL3: =IF(_xlfn.XLOOKUP($A3,'Correspondances pays'!$A$4:$A$205,'Correspondances pays'!$C$4:$C$205)=Résultats!AL$2,1,0) -> 1 | AM3: =IF(_xlfn.XLOOKUP($A3,'Correspondances pays'!$A$4:$A$205,'Correspondances pays'!$C$4:$C$205)=Résultats!AM$2,1,0) -> 0 | AN3: =IF(_xlfn.XLOOKUP($A3,'Correspondances pays'!$A$4:$A$205,'Correspondances pays'!$C$4:$C$205)=Résultats!AN$2,1,0) -> 0 | AO3: =IF(_xlfn.XLOOKUP($A3,'Correspondances pays'!$A$4:$A$205,'Correspondances pays'!$C$4:$C$205)=Résultats!AO$2,1,0) -> 0 | ... AQ3: =IF(_xlfn.XLOOKUP($A3,'Correspondances pays'!$A$4:$A$205,'Correspondances pays'!$C$4:$C$205)=Résultats!AQ$2,1,0) -> 0 | AS3: =(AutoConsommation!J3)/SUM(AutoConsommation!$I3,AutoConsommation!$J3,AutoConsommation!$M3,AutoConsommation!$O3) -> 0.49410129 | AT3: =SUMIF(Import!$E$2:$CN$2,AT$2,Import!$E4:CN4)/Import!$D4 -> 0.010304209 | AU3: =SUMIF(Import!$E$2:$CN$2,AU$2,Import!$E4:CO4)/Import!$D4 -> 0 | AV3: =SUMIF(Import!$E$2:$CN$2,AV$2,Import!$E4:CP4)/Import!$D4 -> 0.044535934 | AW3: =SUMIF(Import!$E$2:$CN$2,AW$2,Import!$E4:CQ4)/Import!$D4 -> 0.02858019 | AX3: =SUMIF(Import!$E$2:$CN$2,AX$2,Import!$E4:CR4)/Import!$D4 -> 0.71914767 | AY3: =SUMIF(Import!$E$2:$CN$2,AY$2,Import!$E4:CS4)/Import!$D4 -> 0.11697815 | AZ3: =SUMIF(Import!$E$2:$CN$2,AZ$2,Import!$E4:CT4)/Import!$D4 -> 0.060053254 | BA3: =SUMIF(Import!$E$2:$CN$2,BA$2,Import!$E4:CU4)/Import!$D4 -> 0 | ... BC3: =SUMIF(Import!$E$2:$CN$2,BC$2,Import!$E4:CW4)/Import!$D4 -> 0.020400594
A4: Austria | B4: Europe | C4: =SUMPRODUCT('Données ArrièrePlan'!$B$3:$M$3,$D4:$O4) -> 0 | D4: =$AC4*AD4 -> 0.52270721 | E4: =$AC4*AE4 -> 0 | F4: =$AG4*AH4+$AS4*AT4 -> 0.0059135359 | G4: =$AG4*AI4+$AS4*AU4 -> 0.0011200933 | H4: =$AG4*AJ4+$AS4*AV4 -> 0.0016192653 | I4: =$AG4*AK4+$AS4*AW4 -> 0.0041873052 | J4: =$AG4*AL4+$AS4*AX4 -> 0.41543894 | K4: =$AG4*AM4+$AS4*AY4 -> 0.027700568 | L4: =$AG4*AN4+$AS4*AZ4 -> 0.013455903 | M4: =$AG4*AO4+$AS4*BA4 -> 0.0009035535 | ... O4: =$AG4*AQ4+$AS4*BC4 -> 0.0069536225 | Q4: =SUMPRODUCT('Données ArrièrePlan'!$D$3:$M$3,R4:AA4) -> 0 | R4: =($AG4*AH4+$AS4*AT4)/($AS4+$AG4) -> 0.012389745 | S4: =($AG4*AI4+$AS4*AU4)/($AS4+$AG4) -> 0.0023467635 | T4: =($AG4*AJ4+$AS4*AV4)/($AS4+$AG4) -> 0.0033926037 | U4: =($AG4*AK4+$AS4*AW4)/($AS4+$AG4) -> 0.0087730326 | V4: =($AG4*AL4+$AS4*AX4)/($AS4+$AG4) -> 0.87040691 | W4: =($AG4*AM4+$AS4*AY4)/($AS4+$AG4) -> 0.058036845 | X4: =($AG4*AN4+$AS4*AZ4)/($AS4+$AG4) -> 0.028192136 | Y4: =($AG4*AO4+$AS4*BA4)/($AS4+$AG4) -> 0.0018930801 | ... AA4: =($AG4*AQ4+$AS4*BC4)/($AS4+$AG4) -> 0.014568882 | AC4: =(AutoConsommation!M4+AutoConsommation!O4)/SUM(AutoConsommation!$I4,AutoConsommation!$J4,AutoConsommation!$M4,AutoConsommation!$O4) -> 0.52270721 | AD4: =IF(_xlfn.XLOOKUP($A4,AutoConsommation!$B:$B,AutoConsommation!$A:$A)=Résultats!AD$2,1,0) -> 1 | AE4: =IF(_xlfn.XLOOKUP($A4,AutoConsommation!$B:$B,AutoConsommation!$A:$A)=Résultats!AE$2,1,0) -> 0 | AG4: =(AutoConsommation!I4)/SUM(AutoConsommation!$I4,AutoConsommation!$J4,AutoConsommation!$M4,AutoConsommation!$O4) -> 0 | AH4: =IF(_xlfn.XLOOKUP($A4,'Correspondances pays'!$A$4:$A$205,'Correspondances pays'!$C$4:$C$205)=Résultats!AH$2,1,0) -> 0 | AI4: =IF(_xlfn.XLOOKUP($A4,'Correspondances pays'!$A$4:$A$205,'Correspondances pays'!$C$4:$C$205)=Résultats!AI$2,1,0) -> 0 | AJ4: =IF(_xlfn.XLOOKUP($A4,'Correspondances pays'!$A$4:$A$205,'Correspondances pays'!$C$4:$C$205)=Résultats!AJ$2,1,0) -> 0 | AK4: =IF(_xlfn.XLOOKUP($A4,'Correspondances pays'!$A$4:$A$205,'Correspondances pays'!$C$4:$C$205)=Résultats!AK$2,1,0) -> 0 | AL4: =IF(_xlfn.XLOOKUP($A4,'Correspondances pays'!$A$4:$A$205,'Correspondances pays'!$C$4:$C$205)=Résultats!AL$2,1,0) -> 1 | AM4: =IF(_xlfn.XLOOKUP($A4,'Correspondances pays'!$A$4:$A$205,'Correspondances pays'!$C$4:$C$205)=Résultats!AM$2,1,0) -> 0 | AN4: =IF(_xlfn.XLOOKUP($A4,'Correspondances pays'!$A$4:$A$205,'Correspondances pays'!$C$4:$C$205)=Résultats!AN$2,1,0) -> 0 | AO4: =IF(_xlfn.XLOOKUP($A4,'Correspondances pays'!$A$4:$A$205,'Correspondances pays'!$C$4:$C$205)=Résultats!AO$2,1,0) -> 0 | ... AQ4: =IF(_xlfn.XLOOKUP($A4,'Correspondances pays'!$A$4:$A$205,'Correspondances pays'!$C$4:$C$205)=Résultats!AQ$2,1,0) -> 0 | AS4: =(AutoConsommation!J4)/SUM(AutoConsommation!$I4,AutoConsommation!$J4,AutoConsommation!$M4,AutoConsommation!$O4) -> 0.47729279 | AT4: =SUMIF(Import!$E$2:$CN$2,AT$2,Import!$E5:CN5)/Import!$D5 -> 0.012389745 | AU4: =SUMIF(Import!$E$2:$CN$2,AU$2,Import!$E5:CO5)/Import!$D5 -> 0.0023467635 | AV4: =SUMIF(Import!$E$2:$CN$2,AV$2,Import!$E5:CP5)/Import!$D5 -> 0.0033926037 | AW4: =SUMIF(Import!$E$2:$CN$2,AW$2,Import!$E5:CQ5)/Import!$D5 -> 0.0087730326 | AX4: =SUMIF(Import!$E$2:$CN$2,AX$2,Import!$E5:CR5)/Import!$D5 -> 0.87040691 | AY4: =SUMIF(Import!$E$2:$CN$2,AY$2,Import!$E5:CS5)/Import!$D5 -> 0.058036845 | AZ4: =SUMIF(Import!$E$2:$CN$2,AZ$2,Import!$E5:CT5)/Import!$D5 -> 0.028192136 | BA4: =SUMIF(Import!$E$2:$CN$2,BA$2,Import!$E5:CU5)/Import!$D5 -> 0.0018930801 | ... BC4: =SUMIF(Import!$E$2:$CN$2,BC$2,Import!$E5:CW5)/Import!$D5 -> 0.014568882
A5: Belgium | B5: Europe | C5: =SUMPRODUCT('Données ArrièrePlan'!$B$3:$M$3,$D5:$O5) -> 0 | D5: =$AC5*AD5 -> 0.55148444 | E5: =$AC5*AE5 -> 0 | F5: =$AG5*AH5+$AS5*AT5 -> 0.00090252486 | G5: =$AG5*AI5+$AS5*AU5 -> 0 | H5: =$AG5*AJ5+$AS5*AV5 -> 0.034823263 | I5: =$AG5*AK5+$AS5*AW5 -> 0.031532596 | J5: =$AG5*AL5+$AS5*AX5 -> 0.34263875 | K5: =$AG5*AM5+$AS5*AY5 -> 0.011377898 | L5: =$AG5*AN5+$AS5*AZ5 -> 0.026425472 | M5: =$AG5*AO5+$AS5*BA5 -> 0.00061478168 | ... O5: =$AG5*AQ5+$AS5*BC5 -> 0 | Q5: =SUMPRODUCT('Données ArrièrePlan'!$D$3:$M$3,R5:AA5) -> 0 | R5: =($AG5*AH5+$AS5*AT5)/($AS5+$AG5) -> 0.0020122487 | S5: =($AG5*AI5+$AS5*AU5)/($AS5+$AG5) -> 0 | T5: =($AG5*AJ5+$AS5*AV5)/($AS5+$AG5) -> 0.077641147 | U5: =($AG5*AK5+$AS5*AW5)/($AS5+$AG5) -> 0.070304353 | V5: =($AG5*AL5+$AS5*AX5)/($AS5+$AG5) -> 0.76393949 | W5: =($AG5*AM5+$AS5*AY5)/($AS5+$AG5) -> 0.0253679 | X5: =($AG5*AN5+$AS5*AZ5)/($AS5+$AG5) -> 0.058917625 | Y5: =($AG5*AO5+$AS5*BA5)/($AS5+$AG5) -> 0.0013707031 | ... AA5: =($AG5*AQ5+$AS5*BC5)/($AS5+$AG5) -> 0 | AC5: =(AutoConsommation!M5+AutoConsommation!O5)/SUM(AutoConsommation!$I5,AutoConsommation!$J5,AutoConsommation!$M5,AutoConsommation!$O5) -> 0.55148444 | AD5: =IF(_xlfn.XLOOKUP($A5,AutoConsommation!$B:$B,AutoConsommation!$A:$A)=Résultats!AD$2,1,0) -> 1 | AE5: =IF(_xlfn.XLOOKUP($A5,AutoConsommation!$B:$B,AutoConsommation!$A:$A)=Résultats!AE$2,1,0) -> 0 | AG5: =(AutoConsommation!I5)/SUM(AutoConsommation!$I5,AutoConsommation!$J5,AutoConsommation!$M5,AutoConsommation!$O5) -> 0 | AH5: =IF(_xlfn.XLOOKUP($A5,'Correspondances pays'!$A$4:$A$205,'Correspondances pays'!$C$4:$C$205)=Résultats!AH$2,1,0) -> 0 | AI5: =IF(_xlfn.XLOOKUP($A5,'Correspondances pays'!$A$4:$A$205,'Correspondances pays'!$C$4:$C$205)=Résultats!AI$2,1,0) -> 0 | AJ5: =IF(_xlfn.XLOOKUP($A5,'Correspondances pays'!$A$4:$A$205,'Correspondances pays'!$C$4:$C$205)=Résultats!AJ$2,1,0) -> 0 | AK5: =IF(_xlfn.XLOOKUP($A5,'Correspondances pays'!$A$4:$A$205,'Correspondances pays'!$C$4:$C$205)=Résultats!AK$2,1,0) -> 0 | AL5: =IF(_xlfn.XLOOKUP($A5,'Correspondances pays'!$A$4:$A$205,'Correspondances pays'!$C$4:$C$205)=Résultats!AL$2,1,0) -> 1 | AM5: =IF(_xlfn.XLOOKUP($A5,'Correspondances pays'!$A$4:$A$205,'Correspondances pays'!$C$4:$C$205)=Résultats!AM$2,1,0) -> 0 | AN5: =IF(_xlfn.XLOOKUP($A5,'Correspondances pays'!$A$4:$A$205,'Correspondances pays'!$C$4:$C$205)=Résultats!AN$2,1,0) -> 0 | AO5: =IF(_xlfn.XLOOKUP($A5,'Correspondances pays'!$A$4:$A$205,'Correspondances pays'!$C$4:$C$205)=Résultats!AO$2,1,0) -> 0 | ... AQ5: =IF(_xlfn.XLOOKUP($A5,'Correspondances pays'!$A$4:$A$205,'Correspondances pays'!$C$4:$C$205)=Résultats!AQ$2,1,0) -> 0 | AS5: =(AutoConsommation!J5)/SUM(AutoConsommation!$I5,AutoConsommation!$J5,AutoConsommation!$M5,AutoConsommation!$O5) -> 0.44851556 | AT5: =SUMIF(Import!$E$2:$CN$2,AT$2,Import!$E6:CN6)/Import!$D6 -> 0.0020122487 | AU5: =SUMIF(Import!$E$2:$CN$2,AU$2,Import!$E6:CO6)/Import!$D6 -> 0 | AV5: =SUMIF(Import!$E$2:$CN$2,AV$2,Import!$E6:CP6)/Import!$D6 -> 0.077641147 | AW5: =SUMIF(Import!$E$2:$CN$2,AW$2,Import!$E6:CQ6)/Import!$D6 -> 0.070304353 | AX5: =SUMIF(Import!$E$2:$CN$2,AX$2,Import!$E6:CR6)/Import!$D6 -> 0.76393949 | AY5: =SUMIF(Import!$E$2:$CN$2,AY$2,Import!$E6:CS6)/Import!$D6 -> 0.0253679 | AZ5: =SUMIF(Import!$E$2:$CN$2,AZ$2,Import!$E6:CT6)/Import!$D6 -> 0.058917625 | BA5: =SUMIF(Import!$E$2:$CN$2,BA$2,Import!$E6:CU6)/Import!$D6 -> 0.0013707031 | ... BC5: =SUMIF(Import!$E$2:$CN$2,BC$2,Import!$E6:CW6)/Import!$D6 -> 0
A6: Brazil | B6: RoW | C6: =SUMPRODUCT('Données ArrièrePlan'!$B$3:$M$3,$D6:$O6) -> 0 | D6: =$AC6*AD6 -> 0 | E6: =$AC6*AE6 -> 0.39920395 | F6: =$AG6*AH6+$AS6*AT6 -> 0.000131888 | G6: =$AG6*AI6+$AS6*AU6 -> 0.00020285312 | H6: =$AG6*AJ6+$AS6*AV6 -> 0.019094303 | I6: =$AG6*AK6+$AS6*AW6 -> 0.050116771 | J6: =$AG6*AL6+$AS6*AX6 -> 0.0064370718 | K6: =$AG6*AM6+$AS6*AY6 -> 0.053660341 | L6: =$AG6*AN6+$AS6*AZ6 -> 0.0047151635 | M6: =$AG6*AO6+$AS6*BA6 -> 0.024241283 | ... O6: =$AG6*AQ6+$AS6*BC6 -> 0.0035509338 | Q6: =SUMPRODUCT('Données ArrièrePlan'!$D$3:$M$3,R6:AA6) -> 0 | R6: =($AG6*AH6+$AS6*AT6)/($AS6+$AG6) -> 0.00021952209 | S6: =($AG6*AI6+$AS6*AU6)/($AS6+$AG6) -> 0.00033764057 | T6: =($AG6*AJ6+$AS6*AV6)/($AS6+$AG6) -> 0.031781672 | U6: =($AG6*AK6+$AS6*AW6)/($AS6+$AG6) -> 0.083417279 | V6: =($AG6*AL6+$AS6*AX6)/($AS6+$AG6) -> 0.010714238 | W6: =($AG6*AM6+$AS6*AY6)/($AS6+$AG6) -> 0.089315403 | X6: =($AG6*AN6+$AS6*AZ6)/($AS6+$AG6) -> 0.0078481932 | Y6: =($AG6*AO6+$AS6*BA6)/($AS6+$AG6) -> 0.040348606 | ... AA6: =($AG6*AQ6+$AS6*BC6)/($AS6+$AG6) -> 0.0059103815 | AC6: =(AutoConsommation!M6+AutoConsommation!O6)/SUM(AutoConsommation!$I6,AutoConsommation!$J6,AutoConsommation!$M6,AutoConsommation!$O6) -> 0.39920395 | AD6: =IF(_xlfn.XLOOKUP($A6,AutoConsommation!$B:$B,AutoConsommation!$A:$A)=Résultats!AD$2,1,0) -> 0 | AE6: =IF(_xlfn.XLOOKUP($A6,AutoConsommation!$B:$B,AutoConsommation!$A:$A)=Résultats!AE$2,1,0) -> 1 | AG6: =(AutoConsommation!I6)/SUM(AutoConsommation!$I6,AutoConsommation!$J6,AutoConsommation!$M6,AutoConsommation!$O6) -> 0.39144627 | AH6: =IF(_xlfn.XLOOKUP($A6,'Correspondances pays'!$A$4:$A$205,'Correspondances pays'!$C$4:$C$205)=Résultats!AH$2,1,0) -> 0 | AI6: =IF(_xlfn.XLOOKUP($A6,'Correspondances pays'!$A$4:$A$205,'Correspondances pays'!$C$4:$C$205)=Résultats!AI$2,1,0) -> 0 | AJ6: =IF(_xlfn.XLOOKUP($A6,'Correspondances pays'!$A$4:$A$205,'Correspondances pays'!$C$4:$C$205)=Résultats!AJ$2,1,0) -> 0 | AK6: =IF(_xlfn.XLOOKUP($A6,'Correspondances pays'!$A$4:$A$205,'Correspondances pays'!$C$4:$C$205)=Résultats!AK$2,1,0) -> 0 | AL6: =IF(_xlfn.XLOOKUP($A6,'Correspondances pays'!$A$4:$A$205,'Correspondances pays'!$C$4:$C$205)=Résultats!AL$2,1,0) -> 0 | AM6: =IF(_xlfn.XLOOKUP($A6,'Correspondances pays'!$A$4:$A$205,'Correspondances pays'!$C$4:$C$205)=Résultats!AM$2,1,0) -> 0 | AN6: =IF(_xlfn.XLOOKUP($A6,'Correspondances pays'!$A$4:$A$205,'Correspondances pays'!$C$4:$C$205)=Résultats!AN$2,1,0) -> 0 | AO6: =IF(_xlfn.XLOOKUP($A6,'Correspondances pays'!$A$4:$A$205,'Correspondances pays'!$C$4:$C$205)=Résultats!AO$2,1,0) -> 0 | ... AQ6: =IF(_xlfn.XLOOKUP($A6,'Correspondances pays'!$A$4:$A$205,'Correspondances pays'!$C$4:$C$205)=Résultats!AQ$2,1,0) -> 0 | AS6: =(AutoConsommation!J6)/SUM(AutoConsommation!$I6,AutoConsommation!$J6,AutoConsommation!$M6,AutoConsommation!$O6) -> 0.20934978 | AT6: =SUMIF(Import!$E$2:$CN$2,AT$2,Import!$E7:CN7)/Import!$D7 -> 0.00062998874 | AU6: =SUMIF(Import!$E$2:$CN$2,AU$2,Import!$E7:CO7)/Import!$D7 -> 0.00096896746 | AV6: =SUMIF(Import!$E$2:$CN$2,AV$2,Import!$E7:CP7)/Import!$D7 -> 0.09120766 | AW6: =SUMIF(Import!$E$2:$CN$2,AW$2,Import!$E7:CQ7)/Import!$D7 -> 0.23939252 | AX6: =SUMIF(Import!$E$2:$CN$2,AX$2,Import!$E7:CR7)/Import!$D7 -> 0.030747928 | AY6: =SUMIF(Import!$E$2:$CN$2,AY$2,Import!$E7:CS7)/Import!$D7 -> 0.25631907 | AZ6: =SUMIF(Import!$E$2:$CN$2,AZ$2,Import!$E7:CT7)/Import!$D7 -> 0.022522897 | BA6: =SUMIF(Import!$E$2:$CN$2,BA$2,Import!$E7:CU7)/Import!$D7 -> 0.11579321 | ... BC6: =SUMIF(Import!$E$2:$CN$2,BC$2,Import!$E7:CW7)/Import!$D7 -> 0.016961727
A7: China | B7: RoW | C7: =SUMPRODUCT('Données ArrièrePlan'!$B$3:$M$3,$D7:$O7) -> 0 | D7: =$AC7*AD7 -> 0 | E7: =$AC7*AE7 -> 0.19368231 | F7: =$AG7*AH7+$AS7*AT7 -> 0 | G7: =$AG7*AI7+$AS7*AU7 -> 0.77132333 | H7: =$AG7*AJ7+$AS7*AV7 -> 0.00098142954 | I7: =$AG7*AK7+$AS7*AW7 -> 0.0081829589 | J7: =$AG7*AL7+$AS7*AX7 -> 0.00023740069 | K7: =$AG7*AM7+$AS7*AY7 -> 0.0013871241 | L7: =$AG7*AN7+$AS7*AZ7 -> 0.010075469 | M7: =$AG7*AO7+$AS7*BA7 -> 0.00054790596 | ... O7: =$AG7*AQ7+$AS7*BC7 -> 0.013105399 | Q7: =SUMPRODUCT('Données ArrièrePlan'!$D$3:$M$3,R7:AA7) -> 0 | R7: =($AG7*AH7+$AS7*AT7)/($AS7+$AG7) -> 0 | S7: =($AG7*AI7+$AS7*AU7)/($AS7+$AG7) -> 0.9565998 | T7: =($AG7*AJ7+$AS7*AV7)/($AS7+$AG7) -> 0.0012171748 | U7: =($AG7*AK7+$AS7*AW7)/($AS7+$AG7) -> 0.010148554 | V7: =($AG7*AL7+$AS7*AX7)/($AS7+$AG7) -> 0.00029442575 | W7: =($AG7*AM7+$AS7*AY7)/($AS7+$AG7) -> 0.0017203196 | X7: =($AG7*AN7+$AS7*AZ7)/($AS7+$AG7) -> 0.012495657 | Y7: =($AG7*AO7+$AS7*BA7)/($AS7+$AG7) -> 0.00067951624 | ... AA7: =($AG7*AQ7+$AS7*BC7)/($AS7+$AG7) -> 0.016253394 | AC7: =(AutoConsommation!M7+AutoConsommation!O7)/SUM(AutoConsommation!$I7,AutoConsommation!$J7,AutoConsommation!$M7,AutoConsommation!$O7) -> 0.19368231 | AD7: =IF(_xlfn.XLOOKUP($A7,AutoConsommation!$B:$B,AutoConsommation!$A:$A)=Résultats!AD$2,1,0) -> 0 | AE7: =IF(_xlfn.XLOOKUP($A7,AutoConsommation!$B:$B,AutoConsommation!$A:$A)=Résultats!AE$2,1,0) -> 1 | AG7: =(AutoConsommation!I7)/SUM(AutoConsommation!$I7,AutoConsommation!$J7,AutoConsommation!$M7,AutoConsommation!$O7) -> 0.77095059 | AH7: =IF(_xlfn.XLOOKUP($A7,'Correspondances pays'!$A$4:$A$205,'Correspondances pays'!$C$4:$C$205)=Résultats!AH$2,1,0) -> 0 | AI7: =IF(_xlfn.XLOOKUP($A7,'Correspondances pays'!$A$4:$A$205,'Correspondances pays'!$C$4:$C$205)=Résultats!AI$2,1,0) -> 1 | AJ7: =IF(_xlfn.XLOOKUP($A7,'Correspondances pays'!$A$4:$A$205,'Correspondances pays'!$C$4:$C$205)=Résultats!AJ$2,1,0) -> 0 | AK7: =IF(_xlfn.XLOOKUP($A7,'Correspondances pays'!$A$4:$A$205,'Correspondances pays'!$C$4:$C$205)=Résultats!AK$2,1,0) -> 0 | AL7: =IF(_xlfn.XLOOKUP($A7,'Correspondances pays'!$A$4:$A$205,'Correspondances pays'!$C$4:$C$205)=Résultats!AL$2,1,0) -> 0 | AM7: =IF(_xlfn.XLOOKUP($A7,'Correspondances pays'!$A$4:$A$205,'Correspondances pays'!$C$4:$C$205)=Résultats!AM$2,1,0) -> 0 | AN7: =IF(_xlfn.XLOOKUP($A7,'Correspondances pays'!$A$4:$A$205,'Correspondances pays'!$C$4:$C$205)=Résultats!AN$2,1,0) -> 0 | AO7: =IF(_xlfn.XLOOKUP($A7,'Correspondances pays'!$A$4:$A$205,'Correspondances pays'!$C$4:$C$205)=Résultats!AO$2,1,0) -> 0 | ... AQ7: =IF(_xlfn.XLOOKUP($A7,'Correspondances pays'!$A$4:$A$205,'Correspondances pays'!$C$4:$C$205)=Résultats!AQ$2,1,0) -> 0 | AS7: =(AutoConsommation!J7)/SUM(AutoConsommation!$I7,AutoConsommation!$J7,AutoConsommation!$M7,AutoConsommation!$O7) -> 0.035367094 | AT7: =SUMIF(Import!$E$2:$CN$2,AT$2,Import!$E8:CN8)/Import!$D8 -> 0 | AU7: =SUMIF(Import!$E$2:$CN$2,AU$2,Import!$E8:CO8)/Import!$D8 -> 0.010539237 | AV7: =SUMIF(Import!$E$2:$CN$2,AV$2,Import!$E8:CP8)/Import!$D8 -> 0.027749793 | AW7: =SUMIF(Import!$E$2:$CN$2,AW$2,Import!$E8:CQ8)/Import!$D8 -> 0.2313721 | AX7: =SUMIF(Import!$E$2:$CN$2,AX$2,Import!$E8:CR8)/Import!$D8 -> 0.0067124737 | AY7: =SUMIF(Import!$E$2:$CN$2,AY$2,Import!$E8:CS8)/Import!$D8 -> 0.039220754 | AZ7: =SUMIF(Import!$E$2:$CN$2,AZ$2,Import!$E8:CT8)/Import!$D8 -> 0.28488259 | BA7: =SUMIF(Import!$E$2:$CN$2,BA$2,Import!$E8:CU8)/Import!$D8 -> 0.01549197 | ... BC7: =SUMIF(Import!$E$2:$CN$2,BC$2,Import!$E8:CW8)/Import!$D8 -> 0.37055346
A8: Korea, South | B8: RoW | C8: =SUMPRODUCT('Données ArrièrePlan'!$B$3:$M$3,$D8:$O8) -> 0 | D8: =$AC8*AD8 -> 0 | E8: =$AC8*AE8 -> 0.47078651 | F8: =$AG8*AH8+$AS8*AT8 -> 0.00095631422 | G8: =$AG8*AI8+$AS8*AU8 -> 0.010167937 | H8: =$AG8*AJ8+$AS8*AV8 -> 0.0002731331 | I8: =$AG8*AK8+$AS8*AW8 -> 0.1903121 | J8: =$AG8*AL8+$AS8*AX8 -> 0.00338908 | K8: =$AG8*AM8+$AS8*AY8 -> 0.11169297 | L8: =$AG8*AN8+$AS8*AZ8 -> 0.048804077 | M8: =$AG8*AO8+$AS8*BA8 -> 0.10854253 | ... O8: =$AG8*AQ8+$AS8*BC8 -> 0.055075338 | Q8: =SUMPRODUCT('Données ArrièrePlan'!$D$3:$M$3,R8:AA8) -> 0 | R8: =($AG8*AH8+$AS8*AT8)/($AS8+$AG8) -> 0.0018070481 | S8: =($AG8*AI8+$AS8*AU8)/($AS8+$AG8) -> 0.019213299 | T8: =($AG8*AJ8+$AS8*AV8)/($AS8+$AG8) -> 0.00051611136 | U8: =($AG8*AK8+$AS8*AW8)/($AS8+$AG8) -> 0.3596131 | V8: =($AG8*AL8+$AS8*AX8)/($AS8+$AG8) -> 0.0064039941 | W8: =($AG8*AM8+$AS8*AY8)/($AS8+$AG8) -> 0.21105466 | X8: =($AG8*AN8+$AS8*AZ8)/($AS8+$AG8) -> 0.092220016 | Y8: =($AG8*AO8+$AS8*BA8)/($AS8+$AG8) -> 0.2051016 | ... AA8: =($AG8*AQ8+$AS8*BC8)/($AS8+$AG8) -> 0.10407017 | AC8: =(AutoConsommation!M8+AutoConsommation!O8)/SUM(AutoConsommation!$I8,AutoConsommation!$J8,AutoConsommation!$M8,AutoConsommation!$O8) -> 0.47078651 | AD8: =IF(_xlfn.XLOOKUP($A8,AutoConsommation!$B:$B,AutoConsommation!$A:$A)=Résultats!AD$2,1,0) -> 0 | AE8: =IF(_xlfn.XLOOKUP($A8,AutoConsommation!$B:$B,AutoConsommation!$A:$A)=Résultats!AE$2,1,0) -> 1 | AG8: =(AutoConsommation!I8)/SUM(AutoConsommation!$I8,AutoConsommation!$J8,AutoConsommation!$M8,AutoConsommation!$O8) -> 0 | AH8: =IF(_xlfn.XLOOKUP($A8,'Correspondances pays'!$A$4:$A$205,'Correspondances pays'!$C$4:$C$205)=Résultats!AH$2,1,0) -> 0 | AI8: =IF(_xlfn.XLOOKUP($A8,'Correspondances pays'!$A$4:$A$205,'Correspondances pays'!$C$4:$C$205)=Résultats!AI$2,1,0) -> 0 | AJ8: =IF(_xlfn.XLOOKUP($A8,'Correspondances pays'!$A$4:$A$205,'Correspondances pays'!$C$4:$C$205)=Résultats!AJ$2,1,0) -> 0 | AK8: =IF(_xlfn.XLOOKUP($A8,'Correspondances pays'!$A$4:$A$205,'Correspondances pays'!$C$4:$C$205)=Résultats!AK$2,1,0) -> 1 | AL8: =IF(_xlfn.XLOOKUP($A8,'Correspondances pays'!$A$4:$A$205,'Correspondances pays'!$C$4:$C$205)=Résultats!AL$2,1,0) -> 0 | AM8: =IF(_xlfn.XLOOKUP($A8,'Correspondances pays'!$A$4:$A$205,'Correspondances pays'!$C$4:$C$205)=Résultats!AM$2,1,0) -> 0 | AN8: =IF(_xlfn.XLOOKUP($A8,'Correspondances pays'!$A$4:$A$205,'Correspondances pays'!$C$4:$C$205)=Résultats!AN$2,1,0) -> 0 | AO8: =IF(_xlfn.XLOOKUP($A8,'Correspondances pays'!$A$4:$A$205,'Correspondances pays'!$C$4:$C$205)=Résultats!AO$2,1,0) -> 0 | ... AQ8: =IF(_xlfn.XLOOKUP($A8,'Correspondances pays'!$A$4:$A$205,'Correspondances pays'!$C$4:$C$205)=Résultats!AQ$2,1,0) -> 0 | AS8: =(AutoConsommation!J8)/SUM(AutoConsommation!$I8,AutoConsommation!$J8,AutoConsommation!$M8,AutoConsommation!$O8) -> 0.52921349 | AT8: =SUMIF(Import!$E$2:$CN$2,AT$2,Import!$E9:CN9)/Import!$D9 -> 0.0018070481 | AU8: =SUMIF(Import!$E$2:$CN$2,AU$2,Import!$E9:CO9)/Import!$D9 -> 0.019213299 | AV8: =SUMIF(Import!$E$2:$CN$2,AV$2,Import!$E9:CP9)/Import!$D9 -> 0.00051611136 | AW8: =SUMIF(Import!$E$2:$CN$2,AW$2,Import!$E9:CQ9)/Import!$D9 -> 0.3596131 | AX8: =SUMIF(Import!$E$2:$CN$2,AX$2,Import!$E9:CR9)/Import!$D9 -> 0.0064039941 | AY8: =SUMIF(Import!$E$2:$CN$2,AY$2,Import!$E9:CS9)/Import!$D9 -> 0.21105466 | AZ8: =SUMIF(Import!$E$2:$CN$2,AZ$2,Import!$E9:CT9)/Import!$D9 -> 0.092220016 | BA8: =SUMIF(Import!$E$2:$CN$2,BA$2,Import!$E9:CU9)/Import!$D9 -> 0.2051016 | ... BC8: =SUMIF(Import!$E$2:$CN$2,BC$2,Import!$E9:CW9)/Import!$D9 -> 0.10407017
A9: Spain | B9: Europe | C9: =SUMPRODUCT('Données ArrièrePlan'!$B$3:$M$3,$D9:$O9) -> 0 | D9: =$AC9*AD9 -> 0.54287318 | E9: =$AC9*AE9 -> 0 | F9: =$AG9*AH9+$AS9*AT9 -> 0 | G9: =$AG9*AI9+$AS9*AU9 -> 0 | H9: =$AG9*AJ9+$AS9*AV9 -> 0.076333662 | I9: =$AG9*AK9+$AS9*AW9 -> 0.054972074 | J9: =$AG9*AL9+$AS9*AX9 -> 0.1561141 | K9: =$AG9*AM9+$AS9*AY9 -> 0.10873981 | L9: =$AG9*AN9+$AS9*AZ9 -> 0.010366242 | M9: =$AG9*AO9+$AS9*BA9 -> 0.0013100781 | ... O9: =$AG9*AQ9+$AS9*BC9 -> 0.041161058 | Q9: =SUMPRODUCT('Données ArrièrePlan'!$D$3:$M$3,R9:AA9) -> 0 | R9: =($AG9*AH9+$AS9*AT9)/($AS9+$AG9) -> 0 | S9: =($AG9*AI9+$AS9*AU9)/($AS9+$AG9) -> 0 | T9: =($AG9*AJ9+$AS9*AV9)/($AS9+$AG9) -> 0.16698574 | U9: =($AG9*AK9+$AS9*AW9)/($AS9+$AG9) -> 0.12025563 | V9: =($AG9*AL9+$AS9*AX9)/($AS9+$AG9) -> 0.34151157 | W9: =($AG9*AM9+$AS9*AY9)/($AS9+$AG9) -> 0.23787667 | X9: =($AG9*AN9+$AS9*AZ9)/($AS9+$AG9) -> 0.022676951 | Y9: =($AG9*AO9+$AS9*BA9)/($AS9+$AG9) -> 0.0028658964 | ... AA9: =($AG9*AQ9+$AS9*BC9)/($AS9+$AG9) -> 0.090042973 | AC9: =(AutoConsommation!M9+AutoConsommation!O9)/SUM(AutoConsommation!$I9,AutoConsommation!$J9,AutoConsommation!$M9,AutoConsommation!$O9) -> 0.54287318 | AD9: =IF(_xlfn.XLOOKUP($A9,AutoConsommation!$B:$B,AutoConsommation!$A:$A)=Résultats!AD$2,1,0) -> 1 | AE9: =IF(_xlfn.XLOOKUP($A9,AutoConsommation!$B:$B,AutoConsommation!$A:$A)=Résultats!AE$2,1,0) -> 0 | AG9: =(AutoConsommation!I9)/SUM(AutoConsommation!$I9,AutoConsommation!$J9,AutoConsommation!$M9,AutoConsommation!$O9) -> 0 | AH9: =IF(_xlfn.XLOOKUP($A9,'Correspondances pays'!$A$4:$A$205,'Correspondances pays'!$C$4:$C$205)=Résultats!AH$2,1,0) -> 0 | AI9: =IF(_xlfn.XLOOKUP($A9,'Correspondances pays'!$A$4:$A$205,'Correspondances pays'!$C$4:$C$205)=Résultats!AI$2,1,0) -> 0 | AJ9: =IF(_xlfn.XLOOKUP($A9,'Correspondances pays'!$A$4:$A$205,'Correspondances pays'!$C$4:$C$205)=Résultats!AJ$2,1,0) -> 0 | AK9: =IF(_xlfn.XLOOKUP($A9,'Correspondances pays'!$A$4:$A$205,'Correspondances pays'!$C$4:$C$205)=Résultats!AK$2,1,0) -> 0 | AL9: =IF(_xlfn.XLOOKUP($A9,'Correspondances pays'!$A$4:$A$205,'Correspondances pays'!$C$4:$C$205)=Résultats!AL$2,1,0) -> 1 | AM9: =IF(_xlfn.XLOOKUP($A9,'Correspondances pays'!$A$4:$A$205,'Correspondances pays'!$C$4:$C$205)=Résultats!AM$2,1,0) -> 0 | AN9: =IF(_xlfn.XLOOKUP($A9,'Correspondances pays'!$A$4:$A$205,'Correspondances pays'!$C$4:$C$205)=Résultats!AN$2,1,0) -> 0 | AO9: =IF(_xlfn.XLOOKUP($A9,'Correspondances pays'!$A$4:$A$205,'Correspondances pays'!$C$4:$C$205)=Résultats!AO$2,1,0) -> 0 | ... AQ9: =IF(_xlfn.XLOOKUP($A9,'Correspondances pays'!$A$4:$A$205,'Correspondances pays'!$C$4:$C$205)=Résultats!AQ$2,1,0) -> 0 | AS9: =(AutoConsommation!J9)/SUM(AutoConsommation!$I9,AutoConsommation!$J9,AutoConsommation!$M9,AutoConsommation!$O9) -> 0.45712682 | AT9: =SUMIF(Import!$E$2:$CN$2,AT$2,Import!$E10:CN10)/Import!$D10 -> 0 | AU9: =SUMIF(Import!$E$2:$CN$2,AU$2,Import!$E10:CO10)/Import!$D10 -> 0 | AV9: =SUMIF(Import!$E$2:$CN$2,AV$2,Import!$E10:CP10)/Import!$D10 -> 0.16698574 | AW9: =SUMIF(Import!$E$2:$CN$2,AW$2,Import!$E10:CQ10)/Import!$D10 -> 0.12025563 | AX9: =SUMIF(Import!$E$2:$CN$2,AX$2,Import!$E10:CR10)/Import!$D10 -> 0.34151157 | AY9: =SUMIF(Import!$E$2:$CN$2,AY$2,Import!$E10:CS10)/Import!$D10 -> 0.23787667 | AZ9: =SUMIF(Import!$E$2:$CN$2,AZ$2,Import!$E10:CT10)/Import!$D10 -> 0.022676951 | BA9: =SUMIF(Import!$E$2:$CN$2,BA$2,Import!$E10:CU10)/Import!$D10 -> 0.0028658964 | ... BC9: =SUMIF(Import!$E$2:$CN$2,BC$2,Import!$E10:CW10)/Import!$D10 -> 0.090042973
A10: United States of America | B10: RoW | C10: =SUMPRODUCT('Données ArrièrePlan'!$B$3:$M$3,$D10:$O10) -> 0 | D10: =$AC10*AD10 -> 0 | E10: =$AC10*AE10 -> 0.34326988 | F10: =$AG10*AH10+$AS10*AT10 -> 0.40417072 | G10: =$AG10*AI10+$AS10*AU10 -> 0.00024963079 | H10: =$AG10*AJ10+$AS10*AV10 -> 0.012877587 | I10: =$AG10*AK10+$AS10*AW10 -> 0.02480277 | J10: =$AG10*AL10+$AS10*AX10 -> 0.0032150556 | K10: =$AG10*AM10+$AS10*AY10 -> 0.12580878 | L10: =$AG10*AN10+$AS10*AZ10 -> 0.026645204 | M10: =$AG10*AO10+$AS10*BA10 -> 0.029044827 | ... O10: =$AG10*AQ10+$AS10*BC10 -> 0.0037275141 | Q10: =SUMPRODUCT('Données ArrièrePlan'!$D$3:$M$3,R10:AA10) -> 0 | R10: =($AG10*AH10+$AS10*AT10)/($AS10+$AG10) -> 0.61542894 | S10: =($AG10*AI10+$AS10*AU10)/($AS10+$AG10) -> 0.00038011168 | T10: =($AG10*AJ10+$AS10*AV10)/($AS10+$AG10) -> 0.019608644 | U10: =($AG10*AK10+$AS10*AW10)/($AS10+$AG10) -> 0.037767067 | V10: =($AG10*AL10+$AS10*AX10)/($AS10+$AG10) -> 0.0048955507 | W10: =($AG10*AM10+$AS10*AY10)/($AS10+$AG10) -> 0.19156846 | X10: =($AG10*AN10+$AS10*AZ10)/($AS10+$AG10) -> 0.040572532 | Y10: =($AG10*AO10+$AS10*BA10)/($AS10+$AG10) -> 0.044226427 | ... AA10: =($AG10*AQ10+$AS10*BC10)/($AS10+$AG10) -> 0.005675869 | AC10: =(AutoConsommation!M10+AutoConsommation!O10)/SUM(AutoConsommation!$I10,AutoConsommation!$J10,AutoConsommation!$M10,AutoConsommation!$O10) -> 0.34326988 | AD10: =IF(_xlfn.XLOOKUP($A10,AutoConsommation!$B:$B,AutoConsommation!$A:$A)=Résultats!AD$2,1,0) -> 0 | AE10: =IF(_xlfn.XLOOKUP($A10,AutoConsommation!$B:$B,AutoConsommation!$A:$A)=Résultats!AE$2,1,0) -> 1 | AG10: =(AutoConsommation!I10)/SUM(AutoConsommation!$I10,AutoConsommation!$J10,AutoConsommation!$M10,AutoConsommation!$O10) -> 0.045792316 | AH10: =IF(_xlfn.XLOOKUP($A10,'Correspondances pays'!$A$4:$A$205,'Correspondances pays'!$C$4:$C$205)=Résultats!AH$2,1,0) -> 1 | AI10: =IF(_xlfn.XLOOKUP($A10,'Correspondances pays'!$A$4:$A$205,'Correspondances pays'!$C$4:$C$205)=Résultats!AI$2,1,0) -> 0 | AJ10: =IF(_xlfn.XLOOKUP($A10,'Correspondances pays'!$A$4:$A$205,'Correspondances pays'!$C$4:$C$205)=Résultats!AJ$2,1,0) -> 0 | AK10: =IF(_xlfn.XLOOKUP($A10,'Correspondances pays'!$A$4:$A$205,'Correspondances pays'!$C$4:$C$205)=Résultats!AK$2,1,0) -> 0 | AL10: =IF(_xlfn.XLOOKUP($A10,'Correspondances pays'!$A$4:$A$205,'Correspondances pays'!$C$4:$C$205)=Résultats!AL$2,1,0) -> 0 | AM10: =IF(_xlfn.XLOOKUP($A10,'Correspondances pays'!$A$4:$A$205,'Correspondances pays'!$C$4:$C$205)=Résultats!AM$2,1,0) -> 0 | AN10: =IF(_xlfn.XLOOKUP($A10,'Correspondances pays'!$A$4:$A$205,'Correspondances pays'!$C$4:$C$205)=Résultats!AN$2,1,0) -> 0 | AO10: =IF(_xlfn.XLOOKUP($A10,'Correspondances pays'!$A$4:$A$205,'Correspondances pays'!$C$4:$C$205)=Résultats!AO$2,1,0) -> 0 | ... AQ10: =IF(_xlfn.XLOOKUP($A10,'Correspondances pays'!$A$4:$A$205,'Correspondances pays'!$C$4:$C$205)=Résultats!AQ$2,1,0) -> 0 | AS10: =(AutoConsommation!J10)/SUM(AutoConsommation!$I10,AutoConsommation!$J10,AutoConsommation!$M10,AutoConsommation!$O10) -> 0.6109378 | AT10: =SUMIF(Import!$E$2:$CN$2,AT$2,Import!$E11:CN11)/Import!$D11 -> 0.58660375 | AU10: =SUMIF(Import!$E$2:$CN$2,AU$2,Import!$E11:CO11)/Import!$D11 -> 0.00040860262 | AV10: =SUMIF(Import!$E$2:$CN$2,AV$2,Import!$E11:CP11)/Import!$D11 -> 0.021078393 | AW10: =SUMIF(Import!$E$2:$CN$2,AW$2,Import!$E11:CQ11)/Import!$D11 -> 0.040597865 | AX10: =SUMIF(Import!$E$2:$CN$2,AX$2,Import!$E11:CR11)/Import!$D11 -> 0.0052624925 | AY10: =SUMIF(Import!$E$2:$CN$2,AY$2,Import!$E11:CS11)/Import!$D11 -> 0.20592731 | AZ10: =SUMIF(Import!$E$2:$CN$2,AZ$2,Import!$E11:CT11)/Import!$D11 -> 0.043613612 | BA10: =SUMIF(Import!$E$2:$CN$2,BA$2,Import!$E11:CU11)/Import!$D11 -> 0.047541381 | ... BC10: =SUMIF(Import!$E$2:$CN$2,BC$2,Import!$E11:CW11)/Import!$D11 -> 0.0061012989
A11: Finland | B11: Europe | C11: =SUMPRODUCT('Données ArrièrePlan'!$B$3:$M$3,$D11:$O11) -> 0 | D11: =$AC11*AD11 -> 0.64350695 | E11: =$AC11*AE11 -> 0 | F11: =$AG11*AH11+$AS11*AT11 -> 4.7028512e-05 | G11: =$AG11*AI11+$AS11*AU11 -> 0 | H11: =$AG11*AJ11+$AS11*AV11 -> 0 | I11: =$AG11*AK11+$AS11*AW11 -> 2.9702218e-05 | J11: =$AG11*AL11+$AS11*AX11 -> 0.32872051 | K11: =$AG11*AM11+$AS11*AY11 -> 0.021094962 | L11: =$AG11*AN11+$AS11*AZ11 -> 0.0016208468 | M11: =$AG11*AO11+$AS11*BA11 -> 0.00095813606 | ... O11: =$AG11*AQ11+$AS11*BC11 -> 0.0039203734 | Q11: =SUMPRODUCT('Données ArrièrePlan'!$D$3:$M$3,R11:AA11) -> 0 | R11: =($AG11*AH11+$AS11*AT11)/($AS11+$AG11) -> 0.00013191986 | S11: =($AG11*AI11+$AS11*AU11)/($AS11+$AG11) -> 0 | T11: =($AG11*AJ11+$AS11*AV11)/($AS11+$AG11) -> 0 | U11: =($AG11*AK11+$AS11*AW11)/($AS11+$AG11) -> 8.3317805e-05 | V11: =($AG11*AL11+$AS11*AX11)/($AS11+$AG11) -> 0.92209517 | W11: =($AG11*AM11+$AS11*AY11)/($AS11+$AG11) -> 0.059173559 | X11: =($AG11*AN11+$AS11*AZ11)/($AS11+$AG11) -> 0.0045466436 | Y11: =($AG11*AO11+$AS11*BA11)/($AS11+$AG11) -> 0.0026876711 | ... AA11: =($AG11*AQ11+$AS11*BC11)/($AS11+$AG11) -> 0.010997054 | AC11: =(AutoConsommation!M11+AutoConsommation!O11)/SUM(AutoConsommation!$I11,AutoConsommation!$J11,AutoConsommation!$M11,AutoConsommation!$O11) -> 0.64350695 | AD11: =IF(_xlfn.XLOOKUP($A11,AutoConsommation!$B:$B,AutoConsommation!$A:$A)=Résultats!AD$2,1,0) -> 1 | AE11: =IF(_xlfn.XLOOKUP($A11,AutoConsommation!$B:$B,AutoConsommation!$A:$A)=Résultats!AE$2,1,0) -> 0 | AG11: =(AutoConsommation!I11)/SUM(AutoConsommation!$I11,AutoConsommation!$J11,AutoConsommation!$M11,AutoConsommation!$O11) -> 0 | AH11: =IF(_xlfn.XLOOKUP($A11,'Correspondances pays'!$A$4:$A$205,'Correspondances pays'!$C$4:$C$205)=Résultats!AH$2,1,0) -> 0 | AI11: =IF(_xlfn.XLOOKUP($A11,'Correspondances pays'!$A$4:$A$205,'Correspondances pays'!$C$4:$C$205)=Résultats!AI$2,1,0) -> 0 | AJ11: =IF(_xlfn.XLOOKUP($A11,'Correspondances pays'!$A$4:$A$205,'Correspondances pays'!$C$4:$C$205)=Résultats!AJ$2,1,0) -> 0 | AK11: =IF(_xlfn.XLOOKUP($A11,'Correspondances pays'!$A$4:$A$205,'Correspondances pays'!$C$4:$C$205)=Résultats!AK$2,1,0) -> 0 | AL11: =IF(_xlfn.XLOOKUP($A11,'Correspondances pays'!$A$4:$A$205,'Correspondances pays'!$C$4:$C$205)=Résultats!AL$2,1,0) -> 1 | AM11: =IF(_xlfn.XLOOKUP($A11,'Correspondances pays'!$A$4:$A$205,'Correspondances pays'!$C$4:$C$205)=Résultats!AM$2,1,0) -> 0 | AN11: =IF(_xlfn.XLOOKUP($A11,'Correspondances pays'!$A$4:$A$205,'Correspondances pays'!$C$4:$C$205)=Résultats!AN$2,1,0) -> 0 | AO11: =IF(_xlfn.XLOOKUP($A11,'Correspondances pays'!$A$4:$A$205,'Correspondances pays'!$C$4:$C$205)=Résultats!AO$2,1,0) -> 0 | ... AQ11: =IF(_xlfn.XLOOKUP($A11,'Correspondances pays'!$A$4:$A$205,'Correspondances pays'!$C$4:$C$205)=Résultats!AQ$2,1,0) -> 0 | AS11: =(AutoConsommation!J11)/SUM(AutoConsommation!$I11,AutoConsommation!$J11,AutoConsommation!$M11,AutoConsommation!$O11) -> 0.35649305 | AT11: =SUMIF(Import!$E$2:$CN$2,AT$2,Import!$E12:CN12)/Import!$D12 -> 0.00013191986 | AU11: =SUMIF(Import!$E$2:$CN$2,AU$2,Import!$E12:CO12)/Import!$D12 -> 0 | AV11: =SUMIF(Import!$E$2:$CN$2,AV$2,Import!$E12:CP12)/Import!$D12 -> 0 | AW11: =SUMIF(Import!$E$2:$CN$2,AW$2,Import!$E12:CQ12)/Import!$D12 -> 8.3317805e-05 | AX11: =SUMIF(Import!$E$2:$CN$2,AX$2,Import!$E12:CR12)/Import!$D12 -> 0.92209517 | AY11: =SUMIF(Import!$E$2:$CN$2,AY$2,Import!$E12:CS12)/Import!$D12 -> 0.059173559 | AZ11: =SUMIF(Import!$E$2:$CN$2,AZ$2,Import!$E12:CT12)/Import!$D12 -> 0.0045466436 | BA11: =SUMIF(Import!$E$2:$CN$2,BA$2,Import!$E12:CU12)/Import!$D12 -> 0.0026876711 | ... BC11: =SUMIF(Import!$E$2:$CN$2,BC$2,Import!$E12:CW12)/Import!$D12 -> 0.010997054
A12: France | B12: Europe | C12: =SUMPRODUCT('Données ArrièrePlan'!$B$3:$M$3,$D12:$O12) -> 0 | D12: =$AC12*AD12 -> 0.44279546 | E12: =$AC12*AE12 -> 0 | F12: =$AG12*AH12+$AS12*AT12 -> 0.014526885 | G12: =$AG12*AI12+$AS12*AU12 -> 0 | H12: =$AG12*AJ12+$AS12*AV12 -> 0.032914385 | I12: =$AG12*AK12+$AS12*AW12 -> 0.0066402588 | J12: =$AG12*AL12+$AS12*AX12 -> 0.39341487 | K12: =$AG12*AM12+$AS12*AY12 -> 0.051963464 | L12: =$AG12*AN12+$AS12*AZ12 -> 0.047101198 | M12: =$AG12*AO12+$AS12*BA12 -> 0.010643485 | ... O12: =$AG12*AQ12+$AS12*BC12 -> 0 | Q12: =SUMPRODUCT('Données ArrièrePlan'!$D$3:$M$3,R12:AA12) -> 0 | R12: =($AG12*AH12+$AS12*AT12)/($AS12+$AG12) -> 0.026071009 | S12: =($AG12*AI12+$AS12*AU12)/($AS12+$AG12) -> 0 | T12: =($AG12*AJ12+$AS12*AV12)/($AS12+$AG12) -> 0.059070561 | U12: =($AG12*AK12+$AS12*AW12)/($AS12+$AG12) -> 0.011917094 | V12: =($AG12*AL12+$AS12*AX12)/($AS12+$AG12) -> 0.70605108 | W12: =($AG12*AM12+$AS12*AY12)/($AS12+$AG12) -> 0.09325743 | X12: =($AG12*AN12+$AS12*AZ12)/($AS12+$AG12) -> 0.084531252 | Y12: =($AG12*AO12+$AS12*BA12)/($AS12+$AG12) -> 0.019101576 | ... AA12: =($AG12*AQ12+$AS12*BC12)/($AS12+$AG12) -> 0 | AC12: =(AutoConsommation!M12+AutoConsommation!O12)/SUM(AutoConsommation!$I12,AutoConsommation!$J12,AutoConsommation!$M12,AutoConsommation!$O12) -> 0.44279546 | AD12: =IF(_xlfn.XLOOKUP($A12,AutoConsommation!$B:$B,AutoConsommation!$A:$A)=Résultats!AD$2,1,0) -> 1 | AE12: =IF(_xlfn.XLOOKUP($A12,AutoConsommation!$B:$B,AutoConsommation!$A:$A)=Résultats!AE$2,1,0) -> 0 | AG12: =(AutoConsommation!I12)/SUM(AutoConsommation!$I12,AutoConsommation!$J12,AutoConsommation!$M12,AutoConsommation!$O12) -> 0.094060628 | AH12: =IF(_xlfn.XLOOKUP($A12,'Correspondances pays'!$A$4:$A$205,'Correspondances pays'!$C$4:$C$205)=Résultats!AH$2,1,0) -> 0 | AI12: =IF(_xlfn.XLOOKUP($A12,'Correspondances pays'!$A$4:$A$205,'Correspondances pays'!$C$4:$C$205)=Résultats!AI$2,1,0) -> 0 | AJ12: =IF(_xlfn.XLOOKUP($A12,'Correspondances pays'!$A$4:$A$205,'Correspondances pays'!$C$4:$C$205)=Résultats!AJ$2,1,0) -> 0 | AK12: =IF(_xlfn.XLOOKUP($A12,'Correspondances pays'!$A$4:$A$205,'Correspondances pays'!$C$4:$C$205)=Résultats!AK$2,1,0) -> 0 | AL12: =IF(_xlfn.XLOOKUP($A12,'Correspondances pays'!$A$4:$A$205,'Correspondances pays'!$C$4:$C$205)=Résultats!AL$2,1,0) -> 1 | AM12: =IF(_xlfn.XLOOKUP($A12,'Correspondances pays'!$A$4:$A$205,'Correspondances pays'!$C$4:$C$205)=Résultats!AM$2,1,0) -> 0 | AN12: =IF(_xlfn.XLOOKUP($A12,'Correspondances pays'!$A$4:$A$205,'Correspondances pays'!$C$4:$C$205)=Résultats!AN$2,1,0) -> 0 | AO12: =IF(_xlfn.XLOOKUP($A12,'Correspondances pays'!$A$4:$A$205,'Correspondances pays'!$C$4:$C$205)=Résultats!AO$2,1,0) -> 0 | ... AQ12: =IF(_xlfn.XLOOKUP($A12,'Correspondances pays'!$A$4:$A$205,'Correspondances pays'!$C$4:$C$205)=Résultats!AQ$2,1,0) -> 0 | AS12: =(AutoConsommation!J12)/SUM(AutoConsommation!$I12,AutoConsommation!$J12,AutoConsommation!$M12,AutoConsommation!$O12) -> 0.46314392 | AT12: =SUMIF(Import!$E$2:$CN$2,AT$2,Import!$E13:CN13)/Import!$D13 -> 0.031365811 | AU12: =SUMIF(Import!$E$2:$CN$2,AU$2,Import!$E13:CO13)/Import!$D13 -> 0 | AV12: =SUMIF(Import!$E$2:$CN$2,AV$2,Import!$E13:CP13)/Import!$D13 -> 0.071067294 | AW12: =SUMIF(Import!$E$2:$CN$2,AW$2,Import!$E13:CQ13)/Import!$D13 -> 0.014337355 | AX12: =SUMIF(Import!$E$2:$CN$2,AX$2,Import!$E13:CR13)/Import!$D13 -> 0.64635253 | AY12: =SUMIF(Import!$E$2:$CN$2,AY$2,Import!$E13:CS13)/Import!$D13 -> 0.11219723 | AZ12: =SUMIF(Import!$E$2:$CN$2,AZ$2,Import!$E13:CT13)/Import!$D13 -> 0.10169884 | BA12: =SUMIF(Import!$E$2:$CN$2,BA$2,Import!$E13:CU13)/Import!$D13 -> 0.022980945 | ... BC12: =SUMIF(Import!$E$2:$CN$2,BC$2,Import!$E13:CW13)/Import!$D13 -> 0
A13: Hungary | B13: Europe | C13: =SUMPRODUCT('Données ArrièrePlan'!$B$3:$M$3,$D13:$O13) -> 0 | D13: =$AC13*AD13 -> 0.44292744 | E13: =$AC13*AE13 -> 0 | F13: =$AG13*AH13+$AS13*AT13 -> 0 | G13: =$AG13*AI13+$AS13*AU13 -> 3.9724686e-06 | H13: =$AG13*AJ13+$AS13*AV13 -> 0.00081832853 | I13: =$AG13*AK13+$AS13*AW13 -> 0.0031700299 | J13: =$AG13*AL13+$AS13*AX13 -> 0.54948713 | K13: =$AG13*AM13+$AS13*AY13 -> 4.7669623e-05 | L13: =$AG13*AN13+$AS13*AZ13 -> 0.0035454282 | M13: =$AG13*AO13+$AS13*BA13 -> 0 | ... O13: =$AG13*AQ13+$AS13*BC13 -> 0 | Q13: =SUMPRODUCT('Données ArrièrePlan'!$D$3:$M$3,R13:AA13) -> 0 | R13: =($AG13*AH13+$AS13*AT13)/($AS13+$AG13) -> 0 | S13: =($AG13*AI13+$AS13*AU13)/($AS13+$AG13) -> 7.1309716e-06 | T13: =($AG13*AJ13+$AS13*AV13)/($AS13+$AG13) -> 0.0014689801 | U13: =($AG13*AK13+$AS13*AW13)/($AS13+$AG13) -> 0.0056905153 | V13: =($AG13*AL13+$AS13*AX13)/($AS13+$AG13) -> 0.98638341 | W13: =($AG13*AM13+$AS13*AY13)/($AS13+$AG13) -> 8.5571659e-05 | X13: =($AG13*AN13+$AS13*AZ13)/($AS13+$AG13) -> 0.0063643921 | Y13: =($AG13*AO13+$AS13*BA13)/($AS13+$AG13) -> 0 | ... AA13: =($AG13*AQ13+$AS13*BC13)/($AS13+$AG13) -> 0 | AC13: =(AutoConsommation!M13+AutoConsommation!O13)/SUM(AutoConsommation!$I13,AutoConsommation!$J13,AutoConsommation!$M13,AutoConsommation!$O13) -> 0.44292744 | AD13: =IF(_xlfn.XLOOKUP($A13,AutoConsommation!$B:$B,AutoConsommation!$A:$A)=Résultats!AD$2,1,0) -> 1 | AE13: =IF(_xlfn.XLOOKUP($A13,AutoConsommation!$B:$B,AutoConsommation!$A:$A)=Résultats!AE$2,1,0) -> 0 | AG13: =(AutoConsommation!I13)/SUM(AutoConsommation!$I13,AutoConsommation!$J13,AutoConsommation!$M13,AutoConsommation!$O13) -> 0 | AH13: =IF(_xlfn.XLOOKUP($A13,'Correspondances pays'!$A$4:$A$205,'Correspondances pays'!$C$4:$C$205)=Résultats!AH$2,1,0) -> 0 | AI13: =IF(_xlfn.XLOOKUP($A13,'Correspondances pays'!$A$4:$A$205,'Correspondances pays'!$C$4:$C$205)=Résultats!AI$2,1,0) -> 0 | AJ13: =IF(_xlfn.XLOOKUP($A13,'Correspondances pays'!$A$4:$A$205,'Correspondances pays'!$C$4:$C$205)=Résultats!AJ$2,1,0) -> 0 | AK13: =IF(_xlfn.XLOOKUP($A13,'Correspondances pays'!$A$4:$A$205,'Correspondances pays'!$C$4:$C$205)=Résultats!AK$2,1,0) -> 0 | AL13: =IF(_xlfn.XLOOKUP($A13,'Correspondances pays'!$A$4:$A$205,'Correspondances pays'!$C$4:$C$205)=Résultats!AL$2,1,0) -> 1 | AM13: =IF(_xlfn.XLOOKUP($A13,'Correspondances pays'!$A$4:$A$205,'Correspondances pays'!$C$4:$C$205)=Résultats!AM$2,1,0) -> 0 | AN13: =IF(_xlfn.XLOOKUP($A13,'Correspondances pays'!$A$4:$A$205,'Correspondances pays'!$C$4:$C$205)=Résultats!AN$2,1,0) -> 0 | AO13: =IF(_xlfn.XLOOKUP($A13,'Correspondances pays'!$A$4:$A$205,'Correspondances pays'!$C$4:$C$205)=Résultats!AO$2,1,0) -> 0 | ... AQ13: =IF(_xlfn.XLOOKUP($A13,'Correspondances pays'!$A$4:$A$205,'Correspondances pays'!$C$4:$C$205)=Résultats!AQ$2,1,0) -> 0 | AS13: =(AutoConsommation!J13)/SUM(AutoConsommation!$I13,AutoConsommation!$J13,AutoConsommation!$M13,AutoConsommation!$O13) -> 0.55707256 | AT13: =SUMIF(Import!$E$2:$CN$2,AT$2,Import!$E14:CN14)/Import!$D14 -> 0 | AU13: =SUMIF(Import!$E$2:$CN$2,AU$2,Import!$E14:CO14)/Import!$D14 -> 7.1309716e-06 | AV13: =SUMIF(Import!$E$2:$CN$2,AV$2,Import!$E14:CP14)/Import!$D14 -> 0.0014689801 | AW13: =SUMIF(Import!$E$2:$CN$2,AW$2,Import!$E14:CQ14)/Import!$D14 -> 0.0056905153 | AX13: =SUMIF(Import!$E$2:$CN$2,AX$2,Import!$E14:CR14)/Import!$D14 -> 0.98638341 | AY13: =SUMIF(Import!$E$2:$CN$2,AY$2,Import!$E14:CS14)/Import!$D14 -> 8.5571659e-05 | AZ13: =SUMIF(Import!$E$2:$CN$2,AZ$2,Import!$E14:CT14)/Import!$D14 -> 0.0063643921 | BA13: =SUMIF(Import!$E$2:$CN$2,BA$2,Import!$E14:CU14)/Import!$D14 -> 0 | ... BC13: =SUMIF(Import!$E$2:$CN$2,BC$2,Import!$E14:CW14)/Import!$D14 -> 0
A14: India | B14: RoW | C14: =SUMPRODUCT('Données ArrièrePlan'!$B$3:$M$3,$D14:$O14) -> 0 | D14: =$AC14*AD14 -> 0 | E14: =$AC14*AE14 -> 0.66215134 | F14: =$AG14*AH14+$AS14*AT14 -> 0.00032103269 | G14: =$AG14*AI14+$AS14*AU14 -> 5.2670775e-05 | H14: =$AG14*AJ14+$AS14*AV14 -> 0.00043069152 | I14: =$AG14*AK14+$AS14*AW14 -> 0.2967639 | J14: =$AG14*AL14+$AS14*AX14 -> 5.7506125e-05 | K14: =$AG14*AM14+$AS14*AY14 -> 0.030982331 | L14: =$AG14*AN14+$AS14*AZ14 -> 0.0014381712 | M14: =$AG14*AO14+$AS14*BA14 -> 0 | ... O14: =$AG14*AQ14+$AS14*BC14 -> 0.0077571099 | Q14: =SUMPRODUCT('Données ArrièrePlan'!$D$3:$M$3,R14:AA14) -> 0 | R14: =($AG14*AH14+$AS14*AT14)/($AS14+$AG14) -> 0.00095022634 | S14: =($AG14*AI14+$AS14*AU14)/($AS14+$AG14) -> 0.0001559005 | T14: =($AG14*AJ14+$AS14*AV14)/($AS14+$AG14) -> 0.0012748061 | U14: =($AG14*AK14+$AS14*AW14)/($AS14+$AG14) -> 0.87839301 | V14: =($AG14*AL14+$AS14*AX14)/($AS14+$AG14) -> 0.00017021268 | W14: =($AG14*AM14+$AS14*AY14)/($AS14+$AG14) -> 0.091704764 | X14: =($AG14*AN14+$AS14*AZ14)/($AS14+$AG14) -> 0.0042568504 | Y14: =($AG14*AO14+$AS14*BA14)/($AS14+$AG14) -> 0 | ... AA14: =($AG14*AQ14+$AS14*BC14)/($AS14+$AG14) -> 0.02296031 | AC14: =(AutoConsommation!M14+AutoConsommation!O14)/SUM(AutoConsommation!$I14,AutoConsommation!$J14,AutoConsommation!$M14,AutoConsommation!$O14) -> 0.66215134 | AD14: =IF(_xlfn.XLOOKUP($A14,AutoConsommation!$B:$B,AutoConsommation!$A:$A)=Résultats!AD$2,1,0) -> 0 | AE14: =IF(_xlfn.XLOOKUP($A14,AutoConsommation!$B:$B,AutoConsommation!$A:$A)=Résultats!AE$2,1,0) -> 1 | AG14: =(AutoConsommation!I14)/SUM(AutoConsommation!$I14,AutoConsommation!$J14,AutoConsommation!$M14,AutoConsommation!$O14) -> 0.29348708 | AH14: =IF(_xlfn.XLOOKUP($A14,'Correspondances pays'!$A$4:$A$205,'Correspondances pays'!$C$4:$C$205)=Résultats!AH$2,1,0) -> 0 | AI14: =IF(_xlfn.XLOOKUP($A14,'Correspondances pays'!$A$4:$A$205,'Correspondances pays'!$C$4:$C$205)=Résultats!AI$2,1,0) -> 0 | AJ14: =IF(_xlfn.XLOOKUP($A14,'Correspondances pays'!$A$4:$A$205,'Correspondances pays'!$C$4:$C$205)=Résultats!AJ$2,1,0) -> 0 | AK14: =IF(_xlfn.XLOOKUP($A14,'Correspondances pays'!$A$4:$A$205,'Correspondances pays'!$C$4:$C$205)=Résultats!AK$2,1,0) -> 1 | AL14: =IF(_xlfn.XLOOKUP($A14,'Correspondances pays'!$A$4:$A$205,'Correspondances pays'!$C$4:$C$205)=Résultats!AL$2,1,0) -> 0 | AM14: =IF(_xlfn.XLOOKUP($A14,'Correspondances pays'!$A$4:$A$205,'Correspondances pays'!$C$4:$C$205)=Résultats!AM$2,1,0) -> 0 | AN14: =IF(_xlfn.XLOOKUP($A14,'Correspondances pays'!$A$4:$A$205,'Correspondances pays'!$C$4:$C$205)=Résultats!AN$2,1,0) -> 0 | AO14: =IF(_xlfn.XLOOKUP($A14,'Correspondances pays'!$A$4:$A$205,'Correspondances pays'!$C$4:$C$205)=Résultats!AO$2,1,0) -> 0 | ... AQ14: =IF(_xlfn.XLOOKUP($A14,'Correspondances pays'!$A$4:$A$205,'Correspondances pays'!$C$4:$C$205)=Résultats!AQ$2,1,0) -> 0 | AS14: =(AutoConsommation!J14)/SUM(AutoConsommation!$I14,AutoConsommation!$J14,AutoConsommation!$M14,AutoConsommation!$O14) -> 0.044361572 | AT14: =SUMIF(Import!$E$2:$CN$2,AT$2,Import!$E15:CN15)/Import!$D15 -> 0.0072367294 | AU14: =SUMIF(Import!$E$2:$CN$2,AU$2,Import!$E15:CO15)/Import!$D15 -> 0.0011873063 | AV14: =SUMIF(Import!$E$2:$CN$2,AV$2,Import!$E15:CP15)/Import!$D15 -> 0.0097086623 | AW14: =SUMIF(Import!$E$2:$CN$2,AW$2,Import!$E15:CQ15)/Import!$D15 -> 0.073866025 | AX14: =SUMIF(Import!$E$2:$CN$2,AX$2,Import!$E15:CR15)/Import!$D15 -> 0.0012963049 | AY14: =SUMIF(Import!$E$2:$CN$2,AY$2,Import!$E15:CS15)/Import!$D15 -> 0.69840473 | AZ14: =SUMIF(Import!$E$2:$CN$2,AZ$2,Import!$E15:CT15)/Import!$D15 -> 0.032419302 | BA14: =SUMIF(Import!$E$2:$CN$2,BA$2,Import!$E15:CU15)/Import!$D15 -> 0 | ... BC14: =SUMIF(Import!$E$2:$CN$2,BC$2,Import!$E15:CW15)/Import!$D15 -> 0.17486103
A15: Indonesia | B15: RoW | C15: =SUMPRODUCT('Données ArrièrePlan'!$B$3:$M$3,$D15:$O15) -> 0 | D15: =$AC15*AD15 -> 0 | E15: =$AC15*AE15 -> 0.60481894 | F15: =$AG15*AH15+$AS15*AT15 -> 0 | G15: =$AG15*AI15+$AS15*AU15 -> 0.0080853014 | H15: =$AG15*AJ15+$AS15*AV15 -> 0.017071331 | I15: =$AG15*AK15+$AS15*AW15 -> 0.1536467 | J15: =$AG15*AL15+$AS15*AX15 -> 0.014087006 | K15: =$AG15*AM15+$AS15*AY15 -> 0.086799235 | L15: =$AG15*AN15+$AS15*AZ15 -> 0.019660185 | M15: =$AG15*AO15+$AS15*BA15 -> 0.045095418 | ... O15: =$AG15*AQ15+$AS15*BC15 -> 0.04758511 | Q15: =SUMPRODUCT('Données ArrièrePlan'!$D$3:$M$3,R15:AA15) -> 0 | R15: =($AG15*AH15+$AS15*AT15)/($AS15+$AG15) -> 0 | S15: =($AG15*AI15+$AS15*AU15)/($AS15+$AG15) -> 0.020459739 | T15: =($AG15*AJ15+$AS15*AV15)/($AS15+$AG15) -> 0.043198757 | U15: =($AG15*AK15+$AS15*AW15)/($AS15+$AG15) -> 0.38880076 | V15: =($AG15*AL15+$AS15*AX15)/($AS15+$AG15) -> 0.035646966 | W15: =($AG15*AM15+$AS15*AY15)/($AS15+$AG15) -> 0.21964422 | X15: =($AG15*AN15+$AS15*AZ15)/($AS15+$AG15) -> 0.049749817 | Y15: =($AG15*AO15+$AS15*BA15)/($AS15+$AG15) -> 0.11411331 | ... AA15: =($AG15*AQ15+$AS15*BC15)/($AS15+$AG15) -> 0.12041344 | AC15: =(AutoConsommation!M15+AutoConsommation!O15)/SUM(AutoConsommation!$I15,AutoConsommation!$J15,AutoConsommation!$M15,AutoConsommation!$O15) -> 0.60481894 | AD15: =IF(_xlfn.XLOOKUP($A15,AutoConsommation!$B:$B,AutoConsommation!$A:$A)=Résultats!AD$2,1,0) -> 0 | AE15: =IF(_xlfn.XLOOKUP($A15,AutoConsommation!$B:$B,AutoConsommation!$A:$A)=Résultats!AE$2,1,0) -> 1 | AG15: =(AutoConsommation!I15)/SUM(AutoConsommation!$I15,AutoConsommation!$J15,AutoConsommation!$M15,AutoConsommation!$O15) -> 0.11062189 | AH15: =IF(_xlfn.XLOOKUP($A15,'Correspondances pays'!$A$4:$A$205,'Correspondances pays'!$C$4:$C$205)=Résultats!AH$2,1,0) -> 0 | AI15: =IF(_xlfn.XLOOKUP($A15,'Correspondances pays'!$A$4:$A$205,'Correspondances pays'!$C$4:$C$205)=Résultats!AI$2,1,0) -> 0 | AJ15: =IF(_xlfn.XLOOKUP($A15,'Correspondances pays'!$A$4:$A$205,'Correspondances pays'!$C$4:$C$205)=Résultats!AJ$2,1,0) -> 0 | AK15: =IF(_xlfn.XLOOKUP($A15,'Correspondances pays'!$A$4:$A$205,'Correspondances pays'!$C$4:$C$205)=Résultats!AK$2,1,0) -> 1 | AL15: =IF(_xlfn.XLOOKUP($A15,'Correspondances pays'!$A$4:$A$205,'Correspondances pays'!$C$4:$C$205)=Résultats!AL$2,1,0) -> 0 | AM15: =IF(_xlfn.XLOOKUP($A15,'Correspondances pays'!$A$4:$A$205,'Correspondances pays'!$C$4:$C$205)=Résultats!AM$2,1,0) -> 0 | AN15: =IF(_xlfn.XLOOKUP($A15,'Correspondances pays'!$A$4:$A$205,'Correspondances pays'!$C$4:$C$205)=Résultats!AN$2,1,0) -> 0 | AO15: =IF(_xlfn.XLOOKUP($A15,'Correspondances pays'!$A$4:$A$205,'Correspondances pays'!$C$4:$C$205)=Résultats!AO$2,1,0) -> 0 | ... AQ15: =IF(_xlfn.XLOOKUP($A15,'Correspondances pays'!$A$4:$A$205,'Correspondances pays'!$C$4:$C$205)=Résultats!AQ$2,1,0) -> 0 | AS15: =(AutoConsommation!J15)/SUM(AutoConsommation!$I15,AutoConsommation!$J15,AutoConsommation!$M15,AutoConsommation!$O15) -> 0.28455917 | AT15: =SUMIF(Import!$E$2:$CN$2,AT$2,Import!$E16:CN16)/Import!$D16 -> 0 | AU15: =SUMIF(Import!$E$2:$CN$2,AU$2,Import!$E16:CO16)/Import!$D16 -> 0.028413428 | AV15: =SUMIF(Import!$E$2:$CN$2,AV$2,Import!$E16:CP16)/Import!$D16 -> 0.059992201 | AW15: =SUMIF(Import!$E$2:$CN$2,AW$2,Import!$E16:CQ16)/Import!$D16 -> 0.1511981 | AX15: =SUMIF(Import!$E$2:$CN$2,AX$2,Import!$E16:CR16)/Import!$D16 -> 0.049504663 | AY15: =SUMIF(Import!$E$2:$CN$2,AY$2,Import!$E16:CS16)/Import!$D16 -> 0.30503053 | AZ15: =SUMIF(Import!$E$2:$CN$2,AZ$2,Import!$E16:CT16)/Import!$D16 -> 0.069089974 | BA15: =SUMIF(Import!$E$2:$CN$2,BA$2,Import!$E16:CU16)/Import!$D16 -> 0.15847466 | ... BC15: =SUMIF(Import!$E$2:$CN$2,BC$2,Import!$E16:CW16)/Import!$D16 -> 0.16722396
... A29: Norway | B29: Europe | C29: =SUMPRODUCT('Données ArrièrePlan'!$B$3:$M$3,$D29:$O29) -> 0 | D29: =$AC29*AD29 -> 0.56444245 | E29: =$AC29*AE29 -> 0 | F29: =$AG29*AH29+$AS29*AT29 -> 0 | G29: =$AG29*AI29+$AS29*AU29 -> 0.0027422836 | H29: =$AG29*AJ29+$AS29*AV29 -> 0.018105188 | I29: =$AG29*AK29+$AS29*AW29 -> 0.031204944 | J29: =$AG29*AL29+$AS29*AX29 -> 0.081317034 | K29: =$AG29*AM29+$AS29*AY29 -> 0.064749495 | L29: =$AG29*AN29+$AS29*AZ29 -> 0.22203322 | M29: =$AG29*AO29+$AS29*BA29 -> 0.0033624407 | ... O29: =$AG29*AQ29+$AS29*BC29 -> 0.012042941 | Q29: =SUMPRODUCT('Données ArrièrePlan'!$D$3:$M$3,R29:AA29) -> 0 | R29: =($AG29*AH29+$AS29*AT29)/($AS29+$AG29) -> 0 | S29: =($AG29*AI29+$AS29*AU29)/($AS29+$AG29) -> 0.0062960305 | T29: =($AG29*AJ29+$AS29*AV29)/($AS29+$AG29) -> 0.041567844 | U29: =($AG29*AK29+$AS29*AW29)/($AS29+$AG29) -> 0.071643677 | V29: =($AG29*AL29+$AS29*AX29)/($AS29+$AG29) -> 0.18669642 | W29: =($AG29*AM29+$AS29*AY29)/($AS29+$AG29) -> 0.14865888 | X29: =($AG29*AN29+$AS29*AZ29)/($AS29+$AG29) -> 0.50976782 | Y29: =($AG29*AO29+$AS29*BA29)/($AS29+$AG29) -> 0.007719854 | ... AA29: =($AG29*AQ29+$AS29*BC29)/($AS29+$AG29) -> 0.027649482 | AC29: =(AutoConsommation!M29+AutoConsommation!O29)/SUM(AutoConsommation!$I29,AutoConsommation!$J29,AutoConsommation!$M29,AutoConsommation!$O29) -> 0.56444245 | AD29: =IF(_xlfn.XLOOKUP($A29,AutoConsommation!$B:$B,AutoConsommation!$A:$A)=Résultats!AD$2,1,0) -> 1 | AE29: =IF(_xlfn.XLOOKUP($A29,AutoConsommation!$B:$B,AutoConsommation!$A:$A)=Résultats!AE$2,1,0) -> 0 | AG29: =(AutoConsommation!I29)/SUM(AutoConsommation!$I29,AutoConsommation!$J29,AutoConsommation!$M29,AutoConsommation!$O29) -> 0.051517212 | AH29: =IF(_xlfn.XLOOKUP($A29,'Correspondances pays'!$A$4:$A$205,'Correspondances pays'!$C$4:$C$205)=Résultats!AH$2,1,0) -> 0 | AI29: =IF(_xlfn.XLOOKUP($A29,'Correspondances pays'!$A$4:$A$205,'Correspondances pays'!$C$4:$C$205)=Résultats!AI$2,1,0) -> 0 | AJ29: =IF(_xlfn.XLOOKUP($A29,'Correspondances pays'!$A$4:$A$205,'Correspondances pays'!$C$4:$C$205)=Résultats!AJ$2,1,0) -> 0 | AK29: =IF(_xlfn.XLOOKUP($A29,'Correspondances pays'!$A$4:$A$205,'Correspondances pays'!$C$4:$C$205)=Résultats!AK$2,1,0) -> 0 | AL29: =IF(_xlfn.XLOOKUP($A29,'Correspondances pays'!$A$4:$A$205,'Correspondances pays'!$C$4:$C$205)=Résultats!AL$2,1,0) -> 1 | AM29: =IF(_xlfn.XLOOKUP($A29,'Correspondances pays'!$A$4:$A$205,'Correspondances pays'!$C$4:$C$205)=Résultats!AM$2,1,0) -> 0 | AN29: =IF(_xlfn.XLOOKUP($A29,'Correspondances pays'!$A$4:$A$205,'Correspondances pays'!$C$4:$C$205)=Résultats!AN$2,1,0) -> 0 | AO29: =IF(_xlfn.XLOOKUP($A29,'Correspondances pays'!$A$4:$A$205,'Correspondances pays'!$C$4:$C$205)=Résultats!AO$2,1,0) -> 0 | ... AQ29: =IF(_xlfn.XLOOKUP($A29,'Correspondances pays'!$A$4:$A$205,'Correspondances pays'!$C$4:$C$205)=Résultats!AQ$2,1,0) -> 0 | AS29: =(AutoConsommation!J29)/SUM(AutoConsommation!$I29,AutoConsommation!$J29,AutoConsommation!$M29,AutoConsommation!$O29) -> 0.38404034 | AT29: =SUMIF(Import!$E$2:$CN$2,AT$2,Import!$E30:CN30)/Import!$D30 -> 0 | AU29: =SUMIF(Import!$E$2:$CN$2,AU$2,Import!$E30:CO30)/Import!$D30 -> 0.0071406135 | AV29: =SUMIF(Import!$E$2:$CN$2,AV$2,Import!$E30:CP30)/Import!$D30 -> 0.047143976 | AW29: =SUMIF(Import!$E$2:$CN$2,AW$2,Import!$E30:CQ30)/Import!$D30 -> 0.081254341 | AX29: =SUMIF(Import!$E$2:$CN$2,AX$2,Import!$E30:CR30)/Import!$D30 -> 0.077595551 | AY29: =SUMIF(Import!$E$2:$CN$2,AY$2,Import!$E30:CS30)/Import!$D30 -> 0.16860077 | AZ29: =SUMIF(Import!$E$2:$CN$2,AZ$2,Import!$E30:CT30)/Import!$D30 -> 0.57815078 | BA29: =SUMIF(Import!$E$2:$CN$2,BA$2,Import!$E30:CU30)/Import!$D30 -> 0.0087554362 | ... BC29: =SUMIF(Import!$E$2:$CN$2,BC$2,Import!$E30:CW30)/Import!$D30 -> 0.03135853

Sheet Données ArrièrePlan
B2: Scrap RER | C2: Scrap RoW | D2: Amérique du Nord | E2: Chine | F2: Afrique | G2: Asie hors Chine et pays du Golfe persique | H2: Europe | I2: Pays du Golfe Persique | J2: Russie | K2: Océanie | L2: Amérique du sud | M2: Reste du monde
A3: Indicateur d'impact
A4: Zone retenue pour la modélisation dans Ecobalyse | D4: =Amerique | E4: =RoW | F4: =RoW | J4: =RoW | K4: =RoW | M4: =RoW
A6: *Pour l'aluminium issu du recyclage, calcul selon la CFF

Sheet AutoConsommation
L1: Data Compens8
B2: Pays producteur de VE | C2: Nom compens8 | D2: Production (t) alu primaire | E2: Exports (t) alu primaire | F2: Import (t) alu primaire | G2: Net exports (exports - imports) en t | H2: Net imports (imports - exports) en tonne | I2: Autoconso (prod - exports) - tonne | J2: Imports consommés (t) | K2: Consommé (t) = auto + import consommé | L2: % RIR | M2: EOL Potentially recycled tonnes | N2: Import Alu product (t) | O2: New scraps (t) = % new scrap x (prod+import alu primaire + import produit alu)
A3: RER | B3: Germany | C3: =_xlfn.XLOOKUP(B3,'Correspondances pays'!$A$4:$A$200,'Correspondances pays'!$B$4:$B$200) -> Germany | D3: =SUMIF('compens8-Prod'!$M$3:$M$102,$C3,'compens8-Prod'!$H$3:$H$102) -> 341212 | E3: =SUMIF('compens8-Export'!$M$4:$M$1002,$C3,'compens8-Export'!$H$4:$H$1002) -> 511237 | F3: =SUMIF('compens8-Import'!$M$4:$M$1002,$C3,'compens8-Import'!$H$4:$H$1002) -> 2458801 | G3: =E3-F3 -> -1947564 | H3: =F3-E3 -> 1947564 | I3: =IF(D3>E3,D3-E3,IF(E3>F3,D3-(E3-F3),D3)) -> 341212 | J3: =IF(D3>E3,F3,IF(F3<E3,0,F3-E3)) -> 1947564 | K3: =J3+I3 -> 2288776 | L3: 0.34643987 | M3: 1014186.6 | N3: 1401739.9 | O3: 638666.44
A4: RER | B4: Austria | C4: =_xlfn.XLOOKUP(B4,'Correspondances pays'!$A$4:$A$200,'Correspondances pays'!$B$4:$B$200) -> Austria | D4: =SUMIF('compens8-Prod'!$M$3:$M$102,$C4,'compens8-Prod'!$H$3:$H$102) -> 0 | E4: =SUMIF('compens8-Export'!$M$4:$M$1002,$C4,'compens8-Export'!$H$4:$H$1002) -> 200431 | F4: =SUMIF('compens8-Import'!$M$4:$M$1002,$C4,'compens8-Import'!$H$4:$H$1002) -> 548841 | G4: =E4-F4 -> -348410 | H4: =F4-E4 -> 348410 | I4: =IF(D4>E4,D4-E4,IF(E4>F4,D4-(E4-F4),D4)) -> 0 | J4: =IF(D4>E4,F4,IF(F4<E4,0,F4-E4)) -> 348410 | K4: =J4+I4 -> 348410 | L4: 0.38018451 | M4: 267507.28 | N4: 283669.5 | O4: 114053.94
A5: RER | B5: Belgium | C5: =_xlfn.XLOOKUP(B5,'Correspondances pays'!$A$4:$A$200,'Correspondances pays'!$B$4:$B$200) -> Belgium | D5: =SUMIF('compens8-Prod'!$M$3:$M$102,$C5,'compens8-Prod'!$H$3:$H$102) -> 0 | E5: =SUMIF('compens8-Export'!$M$4:$M$1002,$C5,'compens8-Export'!$H$4:$H$1002) -> 75853 | F5: =SUMIF('compens8-Import'!$M$4:$M$1002,$C5,'compens8-Import'!$H$4:$H$1002) -> 353833 | G5: =E5-F5 -> -277980 | H5: =F5-E5 -> 277980 | I5: =IF(D5>E5,D5-E5,IF(E5>F5,D5-(E5-F5),D5)) -> 0 | J5: =IF(D5>E5,F5,IF(F5<E5,0,F5-E5)) -> 277980 | K5: =J5+I5 -> 277980 | L5: 0.35592383 | M5: 229581.2 | N5: 465266.49 | O5: 112216.63
A6: RoW | B6: Brazil | C6: =_xlfn.XLOOKUP(B6,'Correspondances pays'!$A$4:$A$200,'Correspondances pays'!$B$4:$B$200) -> Brazil | D6: =SUMIF('compens8-Prod'!$M$3:$M$102,$C6,'compens8-Prod'!$H$3:$H$102) -> 810900 | E6: =SUMIF('compens8-Export'!$M$4:$M$1002,$C6,'compens8-Export'!$H$4:$H$1002) -> 226200 | F6: =SUMIF('compens8-Import'!$M$4:$M$1002,$C6,'compens8-Import'!$H$4:$H$1002) -> 312704 | G6: =E6-F6 -> -86504 | H6: =F6-E6 -> 86504 | I6: =IF(D6>E6,D6-E6,IF(E6>F6,D6-(E6-F6),D6)) -> 584700 | J6: =IF(D6>E6,F6,IF(F6<E6,0,F6-E6)) -> 312704 | K6: =J6+I6 -> 897404 | L6: 0.38520746 | M6: 407203.23 | N6: 171494.35 | O6: 189084.36
A7: RoW | B7: China | C7: =_xlfn.XLOOKUP(B7,'Correspondances pays'!$A$4:$A$200,'Correspondances pays'!$B$4:$B$200) -> China | D7: =SUMIF('compens8-Prod'!$M$3:$M$102,$C7,'compens8-Prod'!$H$3:$H$102) -> 40144300 | E7: =SUMIF('compens8-Export'!$M$4:$M$1002,$C7,'compens8-Export'!$H$4:$H$1002) -> 418052 | F7: =SUMIF('compens8-Import'!$M$4:$M$1002,$C7,'compens8-Import'!$H$4:$H$1002) -> 1822428 | G7: =E7-F7 -> -1404376 | H7: =F7-E7 -> 1404376 | I7: =IF(D7>E7,D7-E7,IF(E7>F7,D7-(E7-F7),D7)) -> 39726248 | J7: =IF(D7>E7,F7,IF(F7<E7,0,F7-E7)) -> 1822428 | K7: =J7+I7 -> 41548676 | L7: 0.2296309 | M7: 3509740 | N7: 324119.14 | O7: 6470499.6
A8: RoW | B8: Korea, South | C8: =_xlfn.XLOOKUP(B8,'Correspondances pays'!$A$4:$A$200,'Correspondances pays'!$B$4:$B$200) -> Korea Republic of | D8: =SUMIF('compens8-Prod'!$M$3:$M$102,$C8,'compens8-Prod'!$H$3:$H$102) -> 0 | E8: =SUMIF('compens8-Export'!$M$4:$M$1002,$C8,'compens8-Export'!$H$4:$H$1002) -> 296314 | F8: =SUMIF('compens8-Import'!$M$4:$M$1002,$C8,'compens8-Import'!$H$4:$H$1002) -> 1519052 | G8: =E8-F8 -> -1222738 | H8: =F8-E8 -> 1222738 | I8: =IF(D8>E8,D8-E8,IF(E8>F8,D8-(E8-F8),D8)) -> 0 | J8: =IF(D8>E8,F8,IF(F8<E8,0,F8-E8)) -> 1222738 | K8: =J8+I8 -> 1222738 | L8: 0.4593088 | M8: 844483.23 | N8: 256570.76 | O8: 243260.32
A9: RER | B9: Spain | C9: =_xlfn.XLOOKUP(B9,'Correspondances pays'!$A$4:$A$200,'Correspondances pays'!$B$4:$B$200) -> Spain | D9: =SUMIF('compens8-Prod'!$M$3:$M$102,$C9,'compens8-Prod'!$H$3:$H$102) -> 0 | E9: =SUMIF('compens8-Export'!$M$4:$M$1002,$C9,'compens8-Export'!$H$4:$H$1002) -> 303824 | F9: =SUMIF('compens8-Import'!$M$4:$M$1002,$C9,'compens8-Import'!$H$4:$H$1002) -> 687394.01 | G9: =E9-F9 -> -383570.01 | H9: =F9-E9 -> 383570.01 | I9: =IF(D9>E9,D9-E9,IF(E9>F9,D9-(E9-F9),D9)) -> 0 | J9: =IF(D9>E9,F9,IF(F9<E9,0,F9-E9)) -> 383570.01 | K9: =J9+I9 -> 383570.01 | L9: 0.34656809 | M9: 300330.44 | N9: 445367.95 | O9: 155188.39
A10: RoW | B10: United States of America | C10: =_xlfn.XLOOKUP(B10,'Correspondances pays'!$A$4:$A$200,'Correspondances pays'!$B$4:$B$200) -> United States of America | D10: =SUMIF('compens8-Prod'!$M$3:$M$102,$C10,'compens8-Prod'!$H$3:$H$102) -> 872270 | E10: =SUMIF('compens8-Export'!$M$4:$M$1002,$C10,'compens8-Export'!$H$4:$H$1002) -> 542628 | F10: =SUMIF('compens8-Import'!$M$4:$M$1002,$C10,'compens8-Import'!$H$4:$H$1002) -> 4397916 | G10: =E10-F10 -> -3855288 | H10: =F10-E10 -> 3855288 | I10: =IF(D10>E10,D10-E10,IF(E10>F10,D10-(E10-F10),D10)) -> 329642 | J10: =IF(D10>E10,F10,IF(F10<E10,0,F10-E10)) -> 4397916 | K10: =J10+I10 -> 4727558 | L10: 0.27378296 | M10: 862387.4 | N10: 3472672.2 | O10: 1608685.9
