Workbook
Name Battery_Chemistry: 'BOM & cycles'!$I$2:$U$2

Sheet ReadMe
A2: This tool aims to evaluate the environmental impact of exemples of batteries, and to build up examples in Ecobalyse.
A4: Sheet | B4: Description
A5: EV Battery | B5: Modelling of an EV battery (assembling, aluminium casing)
A6: Cell & CAM | B6: Modelling of an EV battery cells, including CAM and graphite
A7: <1kWh battery | B7: Modelling of a <1kWh battery (assembling, aluminium or plastic casing)
A8: cell recycling | B8: Modelling of cells recycling at end-of-life, CFF method, based on Delegated Act under Article 7 of the Battery Regulation
A9: BOM EOL - DA | B9: Modelling of cells recycling processes, based on Delegated Act under Article 7 of the Battery Regulation
A10: Background data | B10: LCI dataset, to be completed for full use of this tool
A11: GREET BOM | B11: EV Battery BOM from GREET model - calculation for the modelled battery
A12: GREET input data | B12: EV Battery BOM from GREET model - input data for all vehicle sizes
A14: Autors and data sources:
A15: - Analysis, GWP data calculation, data research for EV batteries: ADEME - STM (Caroline MIR, Laurent Gagnepain)
A16: - Remanufacturing of the tool for adaptation to Ecobalyse need, tool for <1kWh batteries: Ecobalyse (Nicolas Planchenault)
A17: - EV Batteries manufacturing data: GREET - R&D Greenhouse gases, Regulated Emissions, and Energy use in Technologies Model ® (2025 Rev.1 .Net)
A18: - <1kWh batteries inventory data: "Batteries in motion: A life cycle assessment and critical resource use analysis of micromobility vehicles with primary Li-ion battery data"
A19: - AA and AAA batteries inventory data: Life cycle impacts of alkaline batteries with a focus on end‐of‐life, Massachusetts Institute of Technology, Materials Systems Lab, 2010
A20: - Background data: BAFU database, Ecobalyse
A22: Important note
A23: This tool currently doesn't include transformation process for metals and plastics, whereas these processes are included in batteries example in Ecobalyse.

Sheet EV Battery
B2: EV Batteries, cells grouped in modules (aluminium casing)
B4: Capaciy (kWh) | C4: 50
B5: Battery Weight (kg) : | C5: =C4*1000/'BOM & cycles'!C28 -> 274.89142
B6: Cell type | C6: NMC811
B7: Battery range | C7: 40-60 kWh
B8: ="Total "&'Background data'!$B$1 -> Total ECS EI3.9.1 (Pts) | C8: =F14+F20+F36+F40 -> 1159994.8
B9: Nombre de cycles | C9: =_xlfn.XLOOKUP('EV Battery'!C6,'BOM & cycles'!$I$31:$U$31,'BOM & cycles'!$I$32:$U$32) -> 1500
B10: ="Total "&'Background data'!$B$1&" par kWh consommé" -> Total ECS EI3.9.1 (Pts) par kWh consommé | C10: ='EV Battery'!C8/C9/'EV Battery'!C4 -> 15.466597
B12: CELLS
B13: % weight | C13: unit | D13: Weight (kg) | E13: Modelling | F13: ECS
B14: Total | C14: kg/battery | D14: ='BOM & cycles'!C25 -> 148.08008 | E14: Cells, NMC811, CN, Ecobalyse | F14: =D14*_xlfn.XLOOKUP($E14,'Background data'!$D:$D,'Background data'!J:J) -> 986361.41
B16: MODULE
B17: % weight | C17: unit | D17: Weight (kg) | E17: Modelling | F17: ECS | H17: LFP | I17: NMC111 | J17: NMC532 | K17: NMC622 | L17: NMC811 | M17: NMC955 | N17: NCA | O17: LMO | P17: LFP (Hydrothermal) | Q17: LMFP | R17: Na-ion Tiamat | S17: LFP - LiM BS | T17: NMC811 - LiM BS
B18: Copper | C18: kg/battery | D18: =SUMIF($H$17:$S$17,$C$6,$H18:$S18)*$D$20 -> 0.62169872 | E18: Copper | F18: =D18*_xlfn.XLOOKUP($E18,'Background data'!$D:$D,'Background data'!J:J) -> 5797.3406 | H18: ='BOM & cycles'!I7*'BOM & cycles'!$F7/'BOM & cycles'!I$26 -> 0.090052407 | I18: ='BOM & cycles'!J7*'BOM & cycles'!$F7/'BOM & cycles'!J$26 -> 0.079430277 | J18: ='BOM & cycles'!K7*'BOM & cycles'!$F7/'BOM & cycles'!K$26 -> 0.077841857 | K18: ='BOM & cycles'!L7*'BOM & cycles'!$F7/'BOM & cycles'!L$26 -> 0.077540949 | L18: ='BOM & cycles'!M7*'BOM & cycles'!$F7/'BOM & cycles'!M$26 -> 0.076472049 | M18: ='BOM & cycles'!N7*'BOM & cycles'!$F7/'BOM & cycles'!N$26 -> 0.075949691 | N18: ='BOM & cycles'!O7*'BOM & cycles'!$F7/'BOM & cycles'!O$26 -> 0.076802 | O18: ='BOM & cycles'!P7*'BOM & cycles'!$F7/'BOM & cycles'!P$26 -> 0.08934328 | ... T18: ='BOM & cycles'!U7*'BOM & cycles'!$F7/'BOM & cycles'!U$26 -> 0.067802969
B19: Wrought Aluminum | C19: kg/battery | D19: =SUMIF($H$17:$S$17,$C$6,$H19:$S19)*$D$20 -> 7.5080524 | E19: Aluminium, market mix, CN, Ecobalyse | F19: =D19*_xlfn.XLOOKUP($E19,'Background data'!$D:$D,'Background data'!J:J) -> 11284.8 | H19: ='BOM & cycles'!I8*'BOM & cycles'!$F8/'BOM & cycles'!I$26 -> 0.90994759 | I19: ='BOM & cycles'!J8*'BOM & cycles'!$F8/'BOM & cycles'!J$26 -> 0.92056972 | J19: ='BOM & cycles'!K8*'BOM & cycles'!$F8/'BOM & cycles'!K$26 -> 0.92215814 | K19: ='BOM & cycles'!L8*'BOM & cycles'!$F8/'BOM & cycles'!L$26 -> 0.92245905 | L19: ='BOM & cycles'!M8*'BOM & cycles'!$F8/'BOM & cycles'!M$26 -> 0.92352795 | M19: ='BOM & cycles'!N8*'BOM & cycles'!$F8/'BOM & cycles'!N$26 -> 0.92405031 | N19: ='BOM & cycles'!O8*'BOM & cycles'!$F8/'BOM & cycles'!O$26 -> 0.923198 | O19: ='BOM & cycles'!P8*'BOM & cycles'!$F8/'BOM & cycles'!P$26 -> 0.91065672 | ... T19: ='BOM & cycles'!U8*'BOM & cycles'!$F8/'BOM & cycles'!U$26 -> 0.93219703
B20: Total | C20: kg/battery | D20: ='BOM & cycles'!$C$26 -> 8.1297511 | F20: =SUM(F18:F19) -> 17082.141 | H20: =SUM(H18:H19) -> 1 | I20: =SUM(I18:I19) -> 1 | J20: =SUM(J18:J19) -> 1 | K20: =SUM(K18:K19) -> 1 | L20: =SUM(L18:L19) -> 1 | M20: =SUM(M18:M19) -> 1 | N20: =SUM(N18:N19) -> 1 | O20: =SUM(O18:O19) -> 1 | ... T20: =SUM(T18:T19) -> 1
B22: PACK
B23: % weight | C23: unit | D23: Weight (kg) | E23: Modelling | F23: ECS | H23: LFP | I23: NMC111 | J23: NMC532 | K23: NMC622 | L23: NMC811 | M23: NMC955 | N23: NCA | O23: LMO | P23: LFP (Hydrothermal) | Q23: LMFP | R23: Na-ion Tiamat | S23: LFP - LiM BS | T23: NMC811 - LiM BS
B24: Copper | C24: kg/battery | D24: =SUMIF($H$17:$S$17,$C$6,$H24:$S24)*$D$36 -> 2.8137227 | E24: Copper | F24: =D24*_xlfn.XLOOKUP($E24,'Background data'!$D:$D,'Background data'!J:J) -> 26237.964 | H24: ='BOM & cycles'!I7*'BOM & cycles'!$G7/'BOM & cycles'!I$27 -> 0.031379914 | I24: ='BOM & cycles'!J7*'BOM & cycles'!$G7/'BOM & cycles'!J$27 -> 0.025349656 | J24: ='BOM & cycles'!K7*'BOM & cycles'!$G7/'BOM & cycles'!K$27 -> 0.024554734 | K24: ='BOM & cycles'!L7*'BOM & cycles'!$G7/'BOM & cycles'!L$27 -> 0.024363657 | L24: ='BOM & cycles'!M7*'BOM & cycles'!$G7/'BOM & cycles'!M$27 -> 0.023708165 | M24: ='BOM & cycles'!N7*'BOM & cycles'!$G7/'BOM & cycles'!N$27 -> 0.023349851 | N24: ='BOM & cycles'!O7*'BOM & cycles'!$G7/'BOM & cycles'!O$27 -> 0.023898044 | O24: ='BOM & cycles'!P7*'BOM & cycles'!$G7/'BOM & cycles'!P$27 -> 0.030796269 | ... T24: ='BOM & cycles'!U7*'BOM & cycles'!$G7/'BOM & cycles'!U$27 -> 0.021506142
B25: Wrought Aluminum | C25: kg/battery | D25: =SUMIF($H$17:$S$17,$C$6,$H25:$S25)*$D$36 -> 23.44937 | E25: Aluminium, market mix, CN, Ecobalyse | F25: =D25*_xlfn.XLOOKUP($E25,'Background data'!$D:$D,'Background data'!J:J) -> 35245.02 | H25: ='BOM & cycles'!I8*'BOM & cycles'!$G8/'BOM & cycles'!I$27 -> 0.21881414 | I25: ='BOM & cycles'!J8*'BOM & cycles'!$G8/'BOM & cycles'!J$27 -> 0.20274271 | J25: ='BOM & cycles'!K8*'BOM & cycles'!$G8/'BOM & cycles'!K$27 -> 0.2007382 | K25: ='BOM & cycles'!L8*'BOM & cycles'!$G8/'BOM & cycles'!L$27 -> 0.20001429 | L25: ='BOM & cycles'!M8*'BOM & cycles'!$G8/'BOM & cycles'!M$27 -> 0.19758221 | M25: ='BOM & cycles'!N8*'BOM & cycles'!$G8/'BOM & cycles'!N$27 -> 0.19604524 | N25: ='BOM & cycles'!O8*'BOM & cycles'!$G8/'BOM & cycles'!O$27 -> 0.19823816 | O25: ='BOM & cycles'!P8*'BOM & cycles'!$G8/'BOM & cycles'!P$27 -> 0.21661748 | ... T25: ='BOM & cycles'!U8*'BOM & cycles'!$G8/'BOM & cycles'!U$27 -> 0.20404412
B26: Cast Aluminum | C26: kg/battery | D26: =SUMIF($H$17:$S$17,$C$6,$H26:$S26)*$D$36 -> 0 | E26: Aluminium, market mix, CN, Ecobalyse | F26: =D26*_xlfn.XLOOKUP($E26,'Background data'!$D:$D,'Background data'!J:J) -> 0 | H26: ='BOM & cycles'!I9*'BOM & cycles'!$G9/'BOM & cycles'!I$27 -> 0 | I26: ='BOM & cycles'!J9*'BOM & cycles'!$G9/'BOM & cycles'!J$27 -> 0 | J26: ='BOM & cycles'!K9*'BOM & cycles'!$G9/'BOM & cycles'!K$27 -> 0 | K26: ='BOM & cycles'!L9*'BOM & cycles'!$G9/'BOM & cycles'!L$27 -> 0 | L26: ='BOM & cycles'!M9*'BOM & cycles'!$G9/'BOM & cycles'!M$27 -> 0 | M26: ='BOM & cycles'!N9*'BOM & cycles'!$G9/'BOM & cycles'!N$27 -> 0 | N26: ='BOM & cycles'!O9*'BOM & cycles'!$G9/'BOM & cycles'!O$27 -> 0 | O26: ='BOM & cycles'!P9*'BOM & cycles'!$G9/'BOM & cycles'!P$27 -> 0 | ... T26: ='BOM & cycles'!U9*'BOM & cycles'!$G9/'BOM & cycles'!U$27 -> 0
B27: Plastic: Polyethylene | C27: kg/battery | D27: =SUMIF($H$17:$S$17,$C$6,$H27:$S27)*$D$36 -> 1.5393919 | E27: Plastique granulé (divers) | F27: =D27*_xlfn.XLOOKUP($E27,'Background data'!$D:$D,'Background data'!J:J) -> 302.61641 | H27: ='BOM & cycles'!I14*'BOM & cycles'!$G14/'BOM & cycles'!I$27 -> 0.023275018 | I27: ='BOM & cycles'!J14*'BOM & cycles'!$G14/'BOM & cycles'!J$27 -> 0.01540926 | J27: ='BOM & cycles'!K14*'BOM & cycles'!$G14/'BOM & cycles'!K$27 -> 0.014482725 | K27: ='BOM & cycles'!L14*'BOM & cycles'!$G14/'BOM & cycles'!L$27 -> 0.014170927 | L27: ='BOM & cycles'!M14*'BOM & cycles'!$G14/'BOM & cycles'!M$27 -> 0.012970773 | M27: ='BOM & cycles'!N14*'BOM & cycles'!$G14/'BOM & cycles'!N$27 -> 0.01235062 | N27: ='BOM & cycles'!O14*'BOM & cycles'!$G14/'BOM & cycles'!O$27 -> 0.013342834 | O27: ='BOM & cycles'!P14*'BOM & cycles'!$G14/'BOM & cycles'!P$27 -> 0.022983632 | ... T27: ='BOM & cycles'!U14*'BOM & cycles'!$G14/'BOM & cycles'!U$27 -> 0
B28: Plastic: Polymer | C28: kg/battery | D28: =SUMIF($H$17:$S$17,$C$6,$H28:$S28)*$D$36 -> 2.6664468 | E28: Plastique granulé (divers) | F28: =D28*_xlfn.XLOOKUP($E28,'Background data'!$D:$D,'Background data'!J:J) -> 524.17486 | H28: ='BOM & cycles'!I15*'BOM & cycles'!$G15/'BOM & cycles'!I$27 -> 0.022023673 | I28: ='BOM & cycles'!J15*'BOM & cycles'!$G15/'BOM & cycles'!J$27 -> 0.022391581 | J28: ='BOM & cycles'!K15*'BOM & cycles'!$G15/'BOM & cycles'!K$27 -> 0.022317641 | K28: ='BOM & cycles'!L15*'BOM & cycles'!$G15/'BOM & cycles'!L$27 -> 0.0224373 | L28: ='BOM & cycles'!M15*'BOM & cycles'!$G15/'BOM & cycles'!M$27 -> 0.022467232 | M28: ='BOM & cycles'!N15*'BOM & cycles'!$G15/'BOM & cycles'!N$27 -> 0.022414088 | N28: ='BOM & cycles'!O15*'BOM & cycles'!$G15/'BOM & cycles'!O$27 -> 0.022472141 | O28: ='BOM & cycles'!P15*'BOM & cycles'!$G15/'BOM & cycles'!P$27 -> 0.021962137 | ... T28: ='BOM & cycles'!U15*'BOM & cycles'!$G15/'BOM & cycles'!U$27 -> 0.023360915
B29: Plastic: Polyethylene Terephthalate | C29: kg/battery | D29: =SUMIF($H$17:$S$17,$C$6,$H29:$S29)*$D$36 -> 0.46731541 | E29: Plastique granulé (divers) | F29: =D29*_xlfn.XLOOKUP($E29,'Background data'!$D:$D,'Background data'!J:J) -> 91.865697 | H29: ='BOM & cycles'!I16*'BOM & cycles'!$G16/'BOM & cycles'!I$27 -> 0.0042545731 | I29: ='BOM & cycles'!J16*'BOM & cycles'!$G16/'BOM & cycles'!J$27 -> 0.0038523151 | J29: ='BOM & cycles'!K16*'BOM & cycles'!$G16/'BOM & cycles'!K$27 -> 0.0040361692 | K29: ='BOM & cycles'!L16*'BOM & cycles'!$G16/'BOM & cycles'!L$27 -> 0.0037789138 | L29: ='BOM & cycles'!M16*'BOM & cycles'!$G16/'BOM & cycles'!M$27 -> 0.0039375561 | M29: ='BOM & cycles'!N16*'BOM & cycles'!$G16/'BOM & cycles'!N$27 -> 0.0038881581 | N29: ='BOM & cycles'!O16*'BOM & cycles'!$G16/'BOM & cycles'!O$27 -> 0.0037453568 | O29: ='BOM & cycles'!P16*'BOM & cycles'!$G16/'BOM & cycles'!P$27 -> 0.004085979 | ... T29: ='BOM & cycles'!U16*'BOM & cycles'!$G16/'BOM & cycles'!U$27 -> 0.0040114703
B30: Steel | C30: kg/battery | D30: =SUMIF($H$17:$S$17,$C$6,$H30:$S30)*$D$36 -> 50.717467 | E30: Steel, market mix | F30: =D30*_xlfn.XLOOKUP($E30,'Background data'!$D:$D,'Background data'!J:J) -> 4579.6551 | H30: ='BOM & cycles'!I17*'BOM & cycles'!$G17/'BOM & cycles'!I$27 -> 0.40018014 | I30: ='BOM & cycles'!J17*'BOM & cycles'!$G17/'BOM & cycles'!J$27 -> 0.42110619 | J30: ='BOM & cycles'!K17*'BOM & cycles'!$G17/'BOM & cycles'!K$27 -> 0.42332292 | K30: ='BOM & cycles'!L17*'BOM & cycles'!$G17/'BOM & cycles'!L$27 -> 0.42418307 | L30: ='BOM & cycles'!M17*'BOM & cycles'!$G17/'BOM & cycles'!M$27 -> 0.42734065 | M30: ='BOM & cycles'!N17*'BOM & cycles'!$G17/'BOM & cycles'!N$27 -> 0.42975582 | N30: ='BOM & cycles'!O17*'BOM & cycles'!$G17/'BOM & cycles'!O$27 -> 0.42697068 | O30: ='BOM & cycles'!P17*'BOM & cycles'!$G17/'BOM & cycles'!P$27 -> 0.40297968 | ... T30: ='BOM & cycles'!U17*'BOM & cycles'!$G17/'BOM & cycles'!U$27 -> 0.43347476
B31: Stainless Steel | C31: kg/battery | D31: =SUMIF($H$17:$S$17,$C$6,$H31:$S31)*$D$36 -> 19.049975 | E31: Chromium steel | F31: =D31*_xlfn.XLOOKUP($E31,'Background data'!$D:$D,'Background data'!J:J) -> 8959.706 | H31: ='BOM & cycles'!I18*'BOM & cycles'!$G18/'BOM & cycles'!I$27 -> 0.15867055 | I31: ='BOM & cycles'!J18*'BOM & cycles'!$G18/'BOM & cycles'!J$27 -> 0.16059338 | J31: ='BOM & cycles'!K18*'BOM & cycles'!$G18/'BOM & cycles'!K$27 -> 0.16049708 | K31: ='BOM & cycles'!L18*'BOM & cycles'!$G18/'BOM & cycles'!L$27 -> 0.16060383 | L31: ='BOM & cycles'!M18*'BOM & cycles'!$G18/'BOM & cycles'!M$27 -> 0.16051332 | M31: ='BOM & cycles'!N18*'BOM & cycles'!$G18/'BOM & cycles'!N$27 -> 0.16055806 | N31: ='BOM & cycles'!O18*'BOM & cycles'!$G18/'BOM & cycles'!O$27 -> 0.16081626 | O31: ='BOM & cycles'!P18*'BOM & cycles'!$G18/'BOM & cycles'!P$27 -> 0.15807631 | ... T31: ='BOM & cycles'!U18*'BOM & cycles'!$G18/'BOM & cycles'!U$27 -> 0.16565013
B32: Ceramic | C32: kg/battery | D32: =SUMIF($H$17:$S$17,$C$6,$H32:$S32)*$D$36 -> 0.13744571 | F32: =D32*_xlfn.XLOOKUP($E32,'Background data'!$D:$D,'Background data'!J:J) -> 0 | H32: ='BOM & cycles'!I19*'BOM & cycles'!$G19/'BOM & cycles'!I$27 -> 0.001001076 | I32: ='BOM & cycles'!J19*'BOM & cycles'!$G19/'BOM & cycles'!J$27 -> 0.00096307877 | J32: ='BOM & cycles'!K19*'BOM & cycles'!$G19/'BOM & cycles'!K$27 -> 0.0011871086 | K32: ='BOM & cycles'!L19*'BOM & cycles'!$G19/'BOM & cycles'!L$27 -> 0.0011809105 | L32: ='BOM & cycles'!M19*'BOM & cycles'!$G19/'BOM & cycles'!M$27 -> 0.0011581047 | M32: ='BOM & cycles'!N19*'BOM & cycles'!$G19/'BOM & cycles'!N$27 -> 0.0011435759 | N32: ='BOM & cycles'!O19*'BOM & cycles'!$G19/'BOM & cycles'!O$27 -> 0.001170424 | O32: ='BOM & cycles'!P19*'BOM & cycles'!$G19/'BOM & cycles'!P$27 -> 0.0010214947 | ... T32: ='BOM & cycles'!U19*'BOM & cycles'!$G19/'BOM & cycles'!U$27 -> 0.00094387537
B33: Thermal Insulation | C33: kg/battery | D33: =SUMIF($H$17:$S$17,$C$6,$H33:$S33)*$D$36 -> 1.0720765 | F33: =D33*_xlfn.XLOOKUP($E33,'Background data'!$D:$D,'Background data'!J:J) -> 0 | H33: ='BOM & cycles'!I20*'BOM & cycles'!$G20/'BOM & cycles'!I$27 -> 0.0085091463 | I33: ='BOM & cycles'!J20*'BOM & cycles'!$G20/'BOM & cycles'!J$27 -> 0.0089084786 | J33: ='BOM & cycles'!K20*'BOM & cycles'!$G20/'BOM & cycles'!K$27 -> 0.0090220253 | K33: ='BOM & cycles'!L20*'BOM & cycles'!$G20/'BOM & cycles'!L$27 -> 0.0089749202 | L33: ='BOM & cycles'!M20*'BOM & cycles'!$G20/'BOM & cycles'!M$27 -> 0.0090332169 | M33: ='BOM & cycles'!N20*'BOM & cycles'!$G20/'BOM & cycles'!N$27 -> 0.0091486072 | N33: ='BOM & cycles'!O20*'BOM & cycles'!$G20/'BOM & cycles'!O$27 -> 0.0091293073 | O33: ='BOM & cycles'!P20*'BOM & cycles'!$G20/'BOM & cycles'!P$27 -> 0.0086827053 | ... T33: ='BOM & cycles'!U20*'BOM & cycles'!$G20/'BOM & cycles'!U$27 -> 0.0094387537
B34: Coolant: Glycol | C34: kg/battery | D34: =SUMIF($H$17:$S$17,$C$6,$H34:$S34)*$D$36 -> 12.287646 | E34: Glycol (Coolant) | F34: =D34*_xlfn.XLOOKUP($E34,'Background data'!$D:$D,'Background data'!J:J) -> 12901.537 | H34: ='BOM & cycles'!I21*'BOM & cycles'!$G21/'BOM & cycles'!I$27 -> 0.10236002 | I34: ='BOM & cycles'!J21*'BOM & cycles'!$G21/'BOM & cycles'!J$27 -> 0.10353097 | J34: ='BOM & cycles'!K21*'BOM & cycles'!$G21/'BOM & cycles'!K$27 -> 0.10375329 | K34: ='BOM & cycles'!L21*'BOM & cycles'!$G21/'BOM & cycles'!L$27 -> 0.10368395 | L34: ='BOM & cycles'!M21*'BOM & cycles'!$G21/'BOM & cycles'!M$27 -> 0.10353456 | M34: ='BOM & cycles'!N21*'BOM & cycles'!$G21/'BOM & cycles'!N$27 -> 0.10337926 | N34: ='BOM & cycles'!O21*'BOM & cycles'!$G21/'BOM & cycles'!O$27 -> 0.10346548 | O34: ='BOM & cycles'!P21*'BOM & cycles'!$G21/'BOM & cycles'!P$27 -> 0.1018941 | ... T34: ='BOM & cycles'!U21*'BOM & cycles'!$G21/'BOM & cycles'!U$27 -> 0.1052421
B35: Electronic Parts | C35: kg/battery | D35: =SUMIF($H$17:$S$17,$C$6,$H35:$S35)*$D$36 -> 4.4807301 | E35: Electronics | F35: =D35*_xlfn.XLOOKUP($E35,'Background data'!$D:$D,'Background data'!J:J) -> 65166.574 | H35: ='BOM & cycles'!I22*'BOM & cycles'!$G22/'BOM & cycles'!I$27 -> 0.029531743 | I35: ='BOM & cycles'!J22*'BOM & cycles'!$G22/'BOM & cycles'!J$27 -> 0.035152375 | J35: ='BOM & cycles'!K22*'BOM & cycles'!$G22/'BOM & cycles'!K$27 -> 0.036088101 | K35: ='BOM & cycles'!L22*'BOM & cycles'!$G22/'BOM & cycles'!L$27 -> 0.036608227 | L35: ='BOM & cycles'!M22*'BOM & cycles'!$G22/'BOM & cycles'!M$27 -> 0.037754214 | M35: ='BOM & cycles'!N22*'BOM & cycles'!$G22/'BOM & cycles'!N$27 -> 0.03796672 | N35: ='BOM & cycles'!O22*'BOM & cycles'!$G22/'BOM & cycles'!O$27 -> 0.036751314 | O35: ='BOM & cycles'!P22*'BOM & cycles'!$G22/'BOM & cycles'!P$27 -> 0.030900216 | ... T35: ='BOM & cycles'!U22*'BOM & cycles'!$G22/'BOM & cycles'!U$27 -> 0.032327731
B36: Total | C36: kg/battery | D36: ='BOM & cycles'!$C$27 -> 118.68159 | F36: =SUM(F24:F35) -> 154009.11 | H36: =SUM(H24:H35) -> 1 | I36: =SUM(I24:I35) -> 1 | J36: =SUM(J24:J35) -> 1 | K36: =SUM(K24:K35) -> 1 | L36: =SUM(L24:L35) -> 1 | M36: =SUM(M24:M35) -> 1 | N36: =SUM(N24:N35) -> 1 | O36: =SUM(O24:O35) -> 1 | ... T36: =SUM(T24:T35) -> 1
B38: Module & Pack assembling
B39: Item | C39: unit | D39: Amount (kWh) | E39: Modelling | F39: ECS | H39: kWh/kgCell | I39: kWh/kWh battery
B40: Electricity consumption | C40: kWh/kgCell | D40: ='BOM & cycles'!$C$25*H40 -> 41.133355 | E40: Electricity mix, CN | F40: =D40*_xlfn.XLOOKUP($E40,'Background data'!$D:$D,'Background data'!J:J) -> 2542.1385 | H40: =I40*1/3.6 -> 0.27777778 | I40: 1

Sheet Cell & CAM
B2: Li-ion Cells, including modeling of CAM and graphite
B4: NMC811
B6: CELL production | G6: =SUM(G7:G21) -> 1982.8076
B7: cell composition - % weight | C7: Unit | D7: Input/output | E7: Input/output | G7: ='Background data'!B1 -> ECS EI3.9.1 (Pts) | I7: LFP | J7: NMC111 | K7: NMC532 | L7: NMC622 | M7: NMC811 | N7: NMC955 | O7: NCA | P7: LMO | Q7: LFP (Hydrothermal) | R7: LMFP | S7: Na-ion Tiamat | T7: LFP - LiM BS | U7: NMC811 - LiM BS
A8: 2 | B8: Cathode Active Material | C8: % in 1kg cell | G8: =_xlfn.XLOOKUP($B$4,$I$7:$U$7,$I8:$U8)*G28 -> 148.26468 | I8: 0.45484541 | J8: 0.4619596 | K8: 0.44693305 | L8: 0.44321027 | M8: 0.42274104 | N8: 0.40907593 | O8: 0.43416002 | P8: 0.50946444 | Q8: 0.45484541 | R8: 0.45484541 | S8: ='BOM & cycles'!S3*'BOM & cycles'!$E3/'BOM & cycles'!S$25 -> 0.54279966 | T8: ='BOM & cycles'!T3*'BOM & cycles'!$E3/'BOM & cycles'!T$25 -> 0.69479212 | U8: ='BOM & cycles'!U3*'BOM & cycles'!$E3/'BOM & cycles'!U$25 -> 0.70158812
A9: 3 | B9: Graphite/Carbon | C9: % in 1kg cell | D9: Graphite | F9: Graphite, Calculation, Tokaï | G9: =_xlfn.XLOOKUP($B$4,$I$7:$U$7,$I9:$U9)*_xlfn.XLOOKUP($F9,'Background data'!$D:$D,'Background data'!H:H) -> 0 | I9: 0.2344565 | J9: 0.26087818 | K9: 0.27500378 | L9: 0.27818341 | M9: 0.29616989 | N9: 0.30815952 | O9: 0.28804669 | P9: 0.20166063 | Q9: 0.2344565 | R9: 0.2344565 | S9: ='BOM & cycles'!S4*'BOM & cycles'!$E4/'BOM & cycles'!S$25 -> 0.2189292 | T9: ='BOM & cycles'!T4*'BOM & cycles'!$E4/'BOM & cycles'!T$25 -> 0.027885235 | U9: ='BOM & cycles'!U4*'BOM & cycles'!$E4/'BOM & cycles'!U$25 -> 0.037241213
A10: 4 | B10: Silicon | C10: % in 1kg cell | D10: Other materials | G10: =_xlfn.XLOOKUP($B$4,$I$7:$U$7,$I10:$U10)*_xlfn.XLOOKUP($F10,'Background data'!$D:$D,'Background data'!H:H) -> 0 | I10: 0 | J10: 0 | K10: 0 | L10: 0 | M10: 0 | N10: 0 | O10: 0 | P10: 0 | Q10: 0 | R10: 0 | S10: ='BOM & cycles'!S5*'BOM & cycles'!$E5/'BOM & cycles'!S$25 -> 0 | T10: ='BOM & cycles'!T5*'BOM & cycles'!$E5/'BOM & cycles'!T$25 -> 0 | U10: ='BOM & cycles'!U5*'BOM & cycles'!$E5/'BOM & cycles'!U$25 -> 0
A11: 5 | B11: Binder | C11: % in 1kg cell | D11: Other materials | F11: Polyvinylfluoride (PVF) | G11: =_xlfn.XLOOKUP($B$4,$I$7:$U$7,$I11:$U11)*_xlfn.XLOOKUP($F11,'Background data'!$D:$D,'Background data'!H:H) -> 0 | I11: 0.014133411 | J11: 0.014864434 | K11: 0.014831997 | L11: 0.014799676 | M11: 0.014761522 | N11: 0.01476825 | O11: 0.014799694 | P11: 0.014599458 | Q11: 0.014133411 | R11: 0.014133411 | S11: ='BOM & cycles'!S6*'BOM & cycles'!$E6/'BOM & cycles'!S$25 -> 0.01681815 | T11: ='BOM & cycles'!T6*'BOM & cycles'!$E6/'BOM & cycles'!T$25 -> 0.10609071 | U11: ='BOM & cycles'!U6*'BOM & cycles'!$E6/'BOM & cycles'!U$25 -> 0.1075639
A12: 6 | B12: Copper | C12: % in 1kg cell | D12: Cu | F12: Copper foil | G12: =_xlfn.XLOOKUP($B$4,$I$7:$U$7,$I12:$U12)*_xlfn.XLOOKUP($F12,'Background data'!$D:$D,'Background data'!H:H) -> 1191.6174 | I12: 0.13792637 | J12: 0.11993724 | K12: 0.11984524 | L12: 0.1202379 | M12: 0.12138825 | N12: 0.12220556 | O12: 0.11999639 | P12: 0.12960023 | Q12: 0.13792637 | R12: 0.13792637 | S12: ='BOM & cycles'!S7*'BOM & cycles'!$E7/'BOM & cycles'!S$25 -> 0.027326839 | T12: ='BOM & cycles'!T7*'BOM & cycles'!$E7/'BOM & cycles'!T$25 -> 0.12757093 | U12: ='BOM & cycles'!U7*'BOM & cycles'!$E7/'BOM & cycles'!U$25 -> 0.11740793
A13: 7 | B13: Wrought Aluminum | C13: % in 1kg cell | D13: Al | F13: Aluminium, virgin, RER, Ecobalyse | G13: =_xlfn.XLOOKUP($B$4,$I$7:$U$7,$I13:$U13)*_xlfn.XLOOKUP($F13,'Background data'!$D:$D,'Background data'!H:H) -> 16.894353 | I13: 0.021237529 | J13: 0.021009405 | K13: 0.021387998 | L13: 0.021502429 | M13: 0.022026536 | N13: 0.022325837 | O13: 0.021646542 | P13: 0.020228002 | Q13: 0.021237529 | R13: 0.021237529 | S13: ='BOM & cycles'!S8*'BOM & cycles'!$E8/'BOM & cycles'!S$25 -> 0.032173596 | T13: ='BOM & cycles'!T8*'BOM & cycles'!$E8/'BOM & cycles'!T$25 -> 0.031873143 | U13: ='BOM & cycles'!U8*'BOM & cycles'!$E8/'BOM & cycles'!U$25 -> 0.024247289
A14: 8 | B14: Electrolyte: LiPF6 | C14: % in 1kg cell | D14: Other materials | F14: Lithium Hexafluorophosphate (LiPF6) | G14: =_xlfn.XLOOKUP($B$4,$I$7:$U$7,$I14:$U14)*_xlfn.XLOOKUP($F14,'Background data'!$D:$D,'Background data'!H:H) -> 0 | I14: 0.020719493 | J14: 0.018279255 | K14: 0.018416319 | L14: 0.018362794 | M14: 0.018512268 | N14: 0.01861879 | O14: 0.018268629 | P14: 0.018765523 | Q14: 0.020719493 | R14: 0.020719493 | S14: ='BOM & cycles'!S10*'BOM & cycles'!$E10/'BOM & cycles'!S$25 -> 0.024500515 | T14: ='BOM & cycles'!T10*'BOM & cycles'!$E10/'BOM & cycles'!T$25 -> 0.011787857 | U14: ='BOM & cycles'!U10*'BOM & cycles'!$E10/'BOM & cycles'!U$25 -> 0.011951545
A15: 9 | B15: Electrolyte: Ethylene Carbonate | C15: % in 1kg cell | D15: Other materials | F15: Ethylene Carbonate | G15: =_xlfn.XLOOKUP($B$4,$I$7:$U$7,$I15:$U15)*_xlfn.XLOOKUP($F15,'Background data'!$D:$D,'Background data'!H:H) -> 0 | I15: 0.057584157 | J15: 0.050792845 | K15: 0.051024265 | L15: 0.05109659 | M15: 0.051417806 | N15: 0.051633491 | O15: 0.050780784 | P15: 0.052129095 | Q15: 0.057584157 | R15: 0.057584157 | S15: ='BOM & cycles'!S11*'BOM & cycles'!$E11/'BOM & cycles'!S$25 -> 0.067895496 | T15: ='BOM & cycles'!T11*'BOM & cycles'!$E11/'BOM & cycles'!T$25 -> 0 | U15: ='BOM & cycles'!U11*'BOM & cycles'!$E11/'BOM & cycles'!U$25 -> 0
A16: 10 | B16: Electrolyte: Dimethyl Carbonate | C16: % in 1kg cell | D16: Other materials | F16: Dimethyl Carbonate | G16: =_xlfn.XLOOKUP($B$4,$I$7:$U$7,$I16:$U16)*_xlfn.XLOOKUP($F16,'Background data'!$D:$D,'Background data'!H:H) -> 0 | I16: 0.057584157 | J16: 0.050792845 | K16: 0.051024265 | L16: 0.05109659 | M16: 0.051417806 | N16: 0.051633491 | O16: 0.050780784 | P16: 0.052129095 | Q16: 0.057584157 | R16: 0.057584157 | S16: ='BOM & cycles'!S12*'BOM & cycles'!$E12/'BOM & cycles'!S$25 -> 0.067895496 | T16: ='BOM & cycles'!T12*'BOM & cycles'!$E12/'BOM & cycles'!T$25 -> 0 | U16: ='BOM & cycles'!U12*'BOM & cycles'!$E12/'BOM & cycles'!U$25 -> 0
A17: 11 | B17: Plastique granulé (PP) | C17: % in 1kg cell | D17: Other materials | F17: Plastique granulé (divers) | G17: =_xlfn.XLOOKUP($B$4,$I$7:$U$7,$I17:$U17)*_xlfn.XLOOKUP($F17,'Background data'!$D:$D,'Background data'!H:H) -> 0.30762929 | I17: 0.0015129692 | J17: 0.0014861979 | K17: 0.0015330908 | L17: 0.0015103419 | M17: 0.0015648921 | N17: 0.0015791354 | O17: 0.0015204676 | P17: 0.0014235296 | Q17: 0.0015129692 | R17: 0.0015129692 | S17: ='BOM & cycles'!S13*'BOM & cycles'!$E13/'BOM & cycles'!S$25 -> 0.0016610519 | T17: ='BOM & cycles'!T13*'BOM & cycles'!$E13/'BOM & cycles'!T$25 -> 0 | U17: ='BOM & cycles'!U13*'BOM & cycles'!$E13/'BOM & cycles'!U$25 -> 0
B18: source : GREET, average for energy batteries
B19: Energy & emission for cell production | C19: Unit | D19: Input/output | G19: GWP
B20: Electricity | C20: kWh/kgCell | D20: Electricity | F20: Electricity mix, CN | G20: =_xlfn.XLOOKUP($B$4,$I$7:$U$7,$I20:$U20)*_xlfn.XLOOKUP($F20,'Background data'!$D:$D,'Background data'!H:H) -> 392.72707 | I20: =I24*OFFSET('GREET input data'!$C$12,0,'BOM & cycles'!I$29-1)/1000 -> 4.4460073 | J20: =J24*OFFSET('GREET input data'!$C$12,0,'BOM & cycles'!J$29-1)/1000 -> 5.5794117 | K20: =K24*OFFSET('GREET input data'!$C$12,0,'BOM & cycles'!K$29-1)/1000 -> 5.8935206 | L20: =L24*OFFSET('GREET input data'!$C$12,0,'BOM & cycles'!L$29-1)/1000 -> 5.9520878 | M20: =M24*OFFSET('GREET input data'!$C$12,0,'BOM & cycles'!M$29-1)/1000 -> 6.3545641 | N20: =N24*OFFSET('GREET input data'!$C$12,0,'BOM & cycles'!N$29-1)/1000 -> 6.609717 | O20: =O24*OFFSET('GREET input data'!$C$12,0,'BOM & cycles'!O$29-1)/1000 -> 6.1255351 | P20: =P24*OFFSET('GREET input data'!$C$12,0,'BOM & cycles'!P$29-1)/1000 -> 4.4765072 | ... R20: =R24*OFFSET('GREET input data'!$C$12,0,'BOM & cycles'!R$29-1)/1000 -> 4.4460073
B21: Heat | C21: MJ/kgCell | D21: Heat | F21: Heat, RoW | G21: =_xlfn.XLOOKUP($B$4,$I$7:$U$7,$I21:$U21)*_xlfn.XLOOKUP($F21,'Background data'!$D:$D,'Background data'!H:H) -> 232.99645 | I21: =I25*OFFSET('GREET input data'!$C$12,0,'BOM & cycles'!I$29-1)/1000 -> 24.00844 | J21: =J25*OFFSET('GREET input data'!$C$12,0,'BOM & cycles'!J$29-1)/1000 -> 30.128823 | K21: =K25*OFFSET('GREET input data'!$C$12,0,'BOM & cycles'!K$29-1)/1000 -> 31.825011 | L21: =L25*OFFSET('GREET input data'!$C$12,0,'BOM & cycles'!L$29-1)/1000 -> 32.141274 | M21: =M25*OFFSET('GREET input data'!$C$12,0,'BOM & cycles'!M$29-1)/1000 -> 34.314646 | N21: =N25*OFFSET('GREET input data'!$C$12,0,'BOM & cycles'!N$29-1)/1000 -> 35.692472 | O21: =O25*OFFSET('GREET input data'!$C$12,0,'BOM & cycles'!O$29-1)/1000 -> 33.07789 | P21: =P25*OFFSET('GREET input data'!$C$12,0,'BOM & cycles'!P$29-1)/1000 -> 24.173139 | ... R21: =R25*OFFSET('GREET input data'!$C$12,0,'BOM & cycles'!R$29-1)/1000 -> 24.00844
B23: Energy & emission for cell production | C23: Unit | D23: Input/output | G23: GWP
B24: Electricity | C24: kWh/kWhCell | D24: Electricity | I24: =47.2*40% -> 18.88 | J24: =47.2*40% -> 18.88 | K24: =47.2*40% -> 18.88 | L24: =47.2*40% -> 18.88 | M24: =47.2*40% -> 18.88 | N24: =47.2*40% -> 18.88 | O24: =47.2*40% -> 18.88 | P24: =47.2*40% -> 18.88 | ... U24: =47.2*40% -> 18.88
B25: Heat | C25: MJ/kWhCell | D25: Heat | I25: =47.2*60%*3.6 -> 101.952 | J25: =47.2*60%*3.6 -> 101.952 | K25: =47.2*60%*3.6 -> 101.952 | L25: =47.2*60%*3.6 -> 101.952 | M25: =47.2*60%*3.6 -> 101.952 | N25: =47.2*60%*3.6 -> 101.952 | O25: =47.2*60%*3.6 -> 101.952 | P25: =47.2*60%*3.6 -> 101.952 | ... U25: =47.2*60%*3.6 -> 101.952
B28: CAM production | G28: =SUM(G29:G54) -> 350.72224 | I28: LMO | J28: NMC111 | K28: LFP (Hydrothermal) | L28: LFP (Solid State) | M28: NMC622 | N28: NMC811 | O28: NCA | P28: NMC532 | Q28: NMC955 | R28: Na-ion Tiamat
B29: Sulfuric acid (H2SO4) | C29: kg/kg CAM | F29: Acid tannic./ citric, CN | G29: =_xlfn.XLOOKUP($B$4,$I$28:$U$28,$I29:$U29)*_xlfn.XLOOKUP($F29,'Background data'!$D:$D,'Background data'!H:H) -> 0 | I29: 0 | J29: 0 | K29: 0 | L29: 0 | M29: 0 | N29: 0 | O29: 0 | P29: 0 | Q29: 0 | R29: 0.2628
B30: Ammonia (NH3) | C30: kg/kg CAM | F30: Ammonia (NH3), CN | G30: =_xlfn.XLOOKUP($B$4,$I$28:$U$28,$I30:$U30)*_xlfn.XLOOKUP($F30,'Background data'!$D:$D,'Background data'!H:H) -> 0 | I30: 0 | J30: 0 | K30: 0 | L30: 0 | M30: 0 | N30: 0 | O30: 0.37 | P30: 0 | Q30: 0 | R30: 0
B31: Nickel Sulfate (NiSO4) | C31: kg/kg CAM | E31: Ni salts | F31: Nickel Sulfate (NiSO4), GLO | G31: =_xlfn.XLOOKUP($B$4,$I$28:$U$28,$I31:$U31)*_xlfn.XLOOKUP($F31,'Background data'!$D:$D,'Background data'!H:H) -> 0 | I31: 0 | J31: 0.56350594 | K31: 0 | L31: 0 | M31: 1.0091514 | N31: 1.3404216 | O31: 1.36 | P31: 0.86843997 | Q31: 1.587 | R31: 0
B32: Cobalt Sulfate (CoSO4) | C32: kg/kg CAM | E32: Co salt | F32: Cobalt Sulfate (CoSO4), CN | G32: =_xlfn.XLOOKUP($B$4,$I$28:$U$28,$I32:$U32)*_xlfn.XLOOKUP($F32,'Background data'!$D:$D,'Background data'!H:H) -> 0 | I32: 0 | J32: 0.56437987 | K32: 0 | L32: 0 | M32: 0.33690549 | N32: 0.16781256 | O32: 0.26 | P32: 0.35013348 | Q32: 0.042 | R32: 0
B33: Manganese Sulfate (MnSO4) | C33: kg/kg CAM | E33: Mn salts | F33: Manganese Sulfate (MnSO4), GLO | G33: =_xlfn.XLOOKUP($B$4,$I$28:$U$28,$I33:$U33)*_xlfn.XLOOKUP($F33,'Background data'!$D:$D,'Background data'!H:H) -> 0 | I33: 0 | J33: 0.5498507 | K33: 0 | L33: 0 | M33: 0.32823233 | N33: 0.16349246 | O33: 0 | P33: 0.49438655 | Q33: 0.041 | R33: 0
B34: Sodium Hydroxide (NaOH) | C34: kg/kg CAM | F34: Sodium Hydroxide (NaOH), GLO | G34: =_xlfn.XLOOKUP($B$4,$I$28:$U$28,$I34:$U34)*_xlfn.XLOOKUP($F34,'Background data'!$D:$D,'Background data'!H:H) -> 0 | I34: 0 | J34: 0.889536 | K34: 0 | L34: 0 | M34: 0.889536 | N34: 0.889536 | O34: 0.88 | P34: 0.889536 | Q34: 0.889536 | R34: 0
B35: Ammonium Hydroxide (NH4OH) | C35: kg/kg CAM | F35: Ammonia (NH3), CN | G35: =_xlfn.XLOOKUP($B$4,$I$28:$U$28,$I35:$U35)*_xlfn.XLOOKUP($F35,'Background data'!$D:$D,'Background data'!H:H) -> 0 | I35: 0 | J35: 0.12352941 | K35: 0 | L35: 0 | M35: 0.12352941 | N35: 0.12352941 | O35: 0 | P35: 0.12352941 | Q35: 0.12352941 | R35: 0
B36: Hydrochloric Acid (HCl) | C36: kg/kg CAM | F36: Hydrochloric Acid (HCl) | G36: =_xlfn.XLOOKUP($B$4,$I$28:$U$28,$I36:$U36)*_xlfn.XLOOKUP($F36,'Background data'!$D:$D,'Background data'!H:H) -> 0 | I36: 0 | J36: 0 | K36: 0 | L36: 0 | M36: 0 | N36: 0 | O36: 0 | P36: 0 | Q36: 0 | R36: 0
B37: Aluminum sulfate (Al2(SO4)3) | C37: kg/kg CAM | F37: Aluminum sulfate (Al2(SO4)3) | G37: =_xlfn.XLOOKUP($B$4,$I$28:$U$28,$I37:$U37)*_xlfn.XLOOKUP($F37,'Background data'!$D:$D,'Background data'!H:H) -> 0 | I37: 0 | J37: 0 | K37: 0 | L37: 0 | M37: 0 | N37: 0 | O37: 0.09 | P37: 0 | Q37: 0 | R37: 0
B38: V2O5 | C38: kg/kg CAM | F38: Manganese Dioxide (MnO2) | G38: =_xlfn.XLOOKUP($B$4,$I$28:$U$28,$I38:$U38)*_xlfn.XLOOKUP($F38,'Background data'!$D:$D,'Background data'!H:H) -> 0 | I38: 0 | J38: 0 | K38: 0 | L38: 0 | M38: 0 | N38: 0 | O38: 0 | P38: 0 | Q38: 0 | R38: 0.4356
B39: Soda ash (Na2CO3) | C39: kg/kg CAM | F39: Soda ash (Na2CO3) | G39: =_xlfn.XLOOKUP($B$4,$I$28:$U$28,$I39:$U39)*_xlfn.XLOOKUP($F39,'Background data'!$D:$D,'Background data'!H:H) -> 0 | I39: 0 | J39: 0 | K39: 0 | L39: 0 | M39: 0 | N39: 0 | O39: 0 | P39: 0 | Q39: 0 | R39: 0
B40: Sodium Hydroxide (NaOH) | C40: kg/kg CAM | F40: Sodium Hydroxide (NaOH), GLO | G40: =_xlfn.XLOOKUP($B$4,$I$28:$U$28,$I40:$U40)*_xlfn.XLOOKUP($F40,'Background data'!$D:$D,'Background data'!H:H) -> 0 | I40: 0 | J40: 0 | K40: 0 | L40: 0 | M40: 0 | N40: 0 | O40: 0 | P40: 0 | Q40: 0 | R40: 0.3016
B41: Lithium Hydoxide (LiOH) | C41: kg/kg CAM | F41: Lithium Hydoxide (LiOH), GLO | G41: =_xlfn.XLOOKUP($B$4,$I$28:$U$28,$I41:$U41)*_xlfn.XLOOKUP($F41,'Background data'!$D:$D,'Background data'!H:H) -> 0 | I41: 0 | J41: 0 | K41: 0.2683756 | L41: 0 | M41: 0 | N41: 0.24619908 | O41: 0.25 | P41: 0 | Q41: 0.246 | R41: 0
B42: Oxygen (O2) | C42: kg/kg CAM | F42: Oxygen (O2) | G42: =_xlfn.XLOOKUP($B$4,$I$28:$U$28,$I42:$U42)*_xlfn.XLOOKUP($F42,'Background data'!$D:$D,'Background data'!H:H) -> 0 | I42: 0 | J42: 0 | K42: 0 | L42: 0 | M42: 0 | N42: 0 | O42: 0.04 | P42: 0 | Q42: 0 | R42: 0
B43: Phosphoric Acid (H3PO4) | C43: kg/kg CAM | F43: Phosphoric Acid (H3PO4) | G43: =_xlfn.XLOOKUP($B$4,$I$28:$U$28,$I43:$U43)*_xlfn.XLOOKUP($F43,'Background data'!$D:$D,'Background data'!H:H) -> 0 | I43: 0 | J43: 0 | K43: 0.36605947 | L43: 0 | M43: 0 | N43: 0 | O43: 0 | P43: 0 | Q43: 0 | R43: 0
B44: Iron Sulfate (FeSO4) | C44: kg/kg CAM | F44: Iron Sulfate (FeSO4) | G44: =_xlfn.XLOOKUP($B$4,$I$28:$U$28,$I44:$U44)*_xlfn.XLOOKUP($F44,'Background data'!$D:$D,'Background data'!H:H) -> 0 | I44: 0 | J44: 0 | K44: 0.56745045 | L44: 0 | M44: 0 | N44: 0 | O44: 0 | P44: 0 | Q44: 0 | R44: 0
B45: Cobalt Oxide (Co3O4) | C45: kg/kg CAM | F45: Cobalt Oxide (Co3O4) | G45: =_xlfn.XLOOKUP($B$4,$I$28:$U$28,$I45:$U45)*_xlfn.XLOOKUP($F45,'Background data'!$D:$D,'Background data'!H:H) -> 0 | I45: 0 | J45: 0 | K45: 0 | L45: 0 | M45: 0 | N45: 0 | O45: 0 | P45: 0 | Q45: 0 | R45: 0
... B50: Mn2O3 | C50: kg/kg CAM | F50: Manganese Dioxide (MnO2) | G50: =_xlfn.XLOOKUP($B$4,$I$28:$U$28,$I50:$U50)*_xlfn.XLOOKUP($F50,'Background data'!$D:$D,'Background data'!H:H) -> 0 | I50: 0.87312668 | J50: 0 | K50: 0 | L50: 0 | M50: 0 | N50: 0 | O50: 0 | P50: 0 | Q50: 0 | R50: 0
...

Sheet <1kWh battery
B2: Batteries with cells assembling without module
B4: Capaciy (Wh) | C4: 500
B5: Your battery Weight (kg) : | D5: let empty if unknown
B6: Casing material | C6: Aluminium
B7: Cell type | C7: NMC622
B9: Battery BOM | C9: Amount (kg) | D9: ECS (Pts) | E9: Modelling
B10: Cells | C10: =$C$4/_xlfn.XLOOKUP($C$7,'GREET input data'!$C$11:$J$11,'GREET input data'!$C$12:$J$12) -> 1.5859981 | D10: =C10*_xlfn.XLOOKUP($E10,'Background data'!$D:$D,'Background data'!J:J) -> 7102.0995 | E10: Cells, LFP Hydro, CN, Ecobalyse
B11: BMS | C11: 0.05 | D11: =C11*_xlfn.XLOOKUP($E11,'Background data'!$D:$D,'Background data'!J:J) -> 727.187 | E11: Electronics
B12: Total excluding Cells and BMS | C12: =IF(ISBLANK($C$5),$C$4/_xlfn.XLOOKUP($C$6,$C$23:$D$23,$C$32:$D$32),C5-C10-C11) -> 1.1111111 | D12: =SUM(D13:D19) -> 1545.3206
B13: Aluminium | C13: =C$12*_xlfn.XLOOKUP($C$6,$C$23:$D$23,$C24:$D24) -> 0.66666667 | D13: =C13*_xlfn.XLOOKUP($E13,'Background data'!$D:$D,'Background data'!J:J) -> 1002.0175 | E13: Aluminium, market mix, CN, Ecobalyse
B14: PC | C14: =C$12*_xlfn.XLOOKUP($C$6,$C$23:$D$23,$C25:$D25) -> 0.27777778 | D14: =C14*_xlfn.XLOOKUP($E14,'Background data'!$D:$D,'Background data'!J:J) -> 352.1316 | E14: Plastique rigide (PC)
B15: ABS | C15: =C$12*_xlfn.XLOOKUP($C$6,$C$23:$D$23,$C26:$D26) -> 0 | D15: =C15*_xlfn.XLOOKUP($E15,'Background data'!$D:$D,'Background data'!J:J) -> 0 | E15: Plastique rigide (ABS)
B16: PA | C16: =C$12*_xlfn.XLOOKUP($C$6,$C$23:$D$23,$C27:$D27) -> 0.11111111 | D16: =C16*_xlfn.XLOOKUP($E16,'Background data'!$D:$D,'Background data'!J:J) -> 21.842421 | E16: Plastique granulé (divers)
B17: Inox | C17: =C$12*_xlfn.XLOOKUP($C$6,$C$23:$D$23,$C28:$D28) -> 0.022222222 | D17: =C17*_xlfn.XLOOKUP($E17,'Background data'!$D:$D,'Background data'!J:J) -> 10.451698 | E17: Chromium steel
B18: Copper (Cables) | C18: =C$12*_xlfn.XLOOKUP($C$6,$C$23:$D$23,$C29:$D29) -> 0.016666667 | D18: =C18*_xlfn.XLOOKUP($E18,'Background data'!$D:$D,'Background data'!J:J) -> 155.41667 | E18: Copper
B19: PVC (Cables) | C19: =C18 -> 0.016666667 | D19: =C19*_xlfn.XLOOKUP($E19,'Background data'!$D:$D,'Background data'!J:J) -> 3.4607284 | E19: Plastique granulé (PVC)
B20: Total Battery weight | C20: =SUM(C10:C12) -> 2.7471092 | D20: =SUM(D10:D12) -> 9374.6072
B22: Data used for calculation :
B23: Pack composition | C23: Aluminium | D23: Plastic
B24: Aluminium | C24: 0.6 | D24: 0.15
B25: PC | C25: 0.25 | D25: 0.45
B26: ABS | D26: 0.15
B27: PA | C27: 0.1 | D27: 0.12
B28: Inox | C28: 0.02 | D28: 0.07
B29: Copper (Cables) | C29: 0.015 | D29: 0.03
B30: PVC (Cables) | C30: 0.015 | D30: 0.03
B31: Total | C31: =SUM(C24:C30) -> 1 | D31: =SUM(D24:D30) -> 1
B32: Specific capacity of casing (Wh/kg) | C32: 450 | D32: 550
B33: Data are estimated based on the following study (see extracted data below):
B34: Batteries in motion: A life cycle assessment and critical resource use analysis of micromobility vehicles with primary Li-ion battery data
B35: https://doi.org/10.1016/j.est.2025.116965
C36: e-bike | D36: e-cargobike | E36: e-scooter | G36: e-bike | H36: e-cargobike | I36: e-scooter
B37: Battery weight (kg) | C37: 2.9854 | D37: 3.26 | E37: 2.8539
B38: Battery capacity (Wh) | C38: 500 | D38: 540 | E38: 360
B39: Specific capacity (Wh/kg) | C39: =C38/C37 -> 167.48174 | D39: =D38/D37 -> 165.64417 | E39: =E38/E37 -> 126.14317
B40: Specific capacity of cells (Wh/kg) | C40: =C38*1000/C60 -> 254.42703 | D40: =D38*1000/D60 -> 238.93805 | E40: =E38*1000/E60 -> 192.71949
B41: Specific capacity of casing (Wh/kg) | C41: =C38*1000/C62 -> 501.90725 | D41: =D38*1000/D62 -> 553.27869 | E41: =E38*1000/E62 -> 394.04553
B42: Weight per cell | C42: 49.13 | D42: 45.2 | E42: 46.7
B43: nb cell | C43: 40 | D43: 50 | E43: 40
B44: Battery composition
...

Sheet cell recycling
A1: Scénario de recyclage | B1: Reglement batterie obj. 2027
A3: LFP cell | B3: Qtty for 1kg | C3: % recovered EoL | D3: Qtty recovered EoL | E3: A | F3: Q | G3: Qtty process | H3: Process selected | I3: Erec CO2 | J3: Erec CE | K3: Ev CO2 | L3: Ev CE | M3: crédit CO2 | N3: crédit CE
A4: Graphite / hard carbon (cell) | B4: ='Cell & CAM'!K66 -> 0.27500378 | C4: =B43 -> 0 | D4: =B4*C4 -> 0 | E4: 0.2 | F4: 0.8 | G4: =$D4*(1-$E4) -> 0 | H4: Graphite, Acheson, EI | K4: =_xlfn.XLOOKUP($H4,'Background data'!$D$1:$D$124,'Background data'!H$1:H$124) -> 0 | L4: =_xlfn.XLOOKUP($H4,'Background data'!$D$1:$D$124,'Background data'!J$1:J$124) -> 0 | M4: =$D4*(1-$E4)*(I4-$F4*K4) -> 0 | N4: =$D4*(1-$E4)*(J4-$F4*L4) -> 0
A5: Al | B5: ='Cell & CAM'!K67 -> 0.021387998 | C5: =B44 -> 0 | D5: =B5*C5 -> 0 | E5: 0.2 | F5: 1 | G5: =$D5*(1-$E5) -> 0 | H5: Aluminium, virgin, RER, Ecobalyse | K5: =_xlfn.XLOOKUP($H5,'Background data'!$D$1:$D$124,'Background data'!H$1:H$124) -> 767 | L5: =_xlfn.XLOOKUP($H5,'Background data'!$D$1:$D$124,'Background data'!J$1:J$124) -> 767 | M5: =$D5*(1-$E5)*(I5-$F5*K5) -> 0 | N5: =$D5*(1-$E5)*(J5-$F5*L5) -> 0
A6: Cu | B6: ='Cell & CAM'!K68 -> 0.11984524 | C6: =B45 -> 0.9 | D6: =B6*C6 -> 0.10786071 | E6: 0.2 | F6: 1 | G6: =$D6*(1-$E6) -> 0.086288571 | H6: Copper | K6: =_xlfn.XLOOKUP($H6,'Background data'!$D$1:$D$124,'Background data'!H$1:H$124) -> 9325 | L6: =_xlfn.XLOOKUP($H6,'Background data'!$D$1:$D$124,'Background data'!J$1:J$124) -> 9325 | M6: =$D6*(1-$E6)*(I6-$F6*K6) -> -804.64092 | N6: =$D6*(1-$E6)*(J6-$F6*L6) -> -804.64092
A7: Fe | B7: ='Cell & CAM'!K69 -> 0 | C7: =B46 -> 0 | D7: =B7*C7 -> 0 | E7: 0.2 | F7: 1 | G7: =$D7*(1-$E7) -> 0 | H7: Steel, virgin | K7: =_xlfn.XLOOKUP($H7,'Background data'!$D$1:$D$124,'Background data'!H$1:H$124) -> 111 | L7: =_xlfn.XLOOKUP($H7,'Background data'!$D$1:$D$124,'Background data'!J$1:J$124) -> 111 | M7: =$D7*(1-$E7)*(I7-$F7*K7) -> 0 | N7: =$D7*(1-$E7)*(J7-$F7*L7) -> 0
A8: Co (cell) salt | B8: ='Cell & CAM'!K70 -> 0.15648622 | C8: =B47 -> 0.9 | D8: =B8*C8 -> 0.1408376 | E8: 0.2 | F8: 0.8 | G8: =$D8*(1-$E8) -> 0.11267008 | H8: Cobalt Sulfate (CoSO4), CN | K8: =_xlfn.XLOOKUP($H8,'Background data'!$D$1:$D$124,'Background data'!H$1:H$124) -> 0 | L8: =_xlfn.XLOOKUP($H8,'Background data'!$D$1:$D$124,'Background data'!J$1:J$124) -> 0 | M8: =$D8*(1-$E8)*(I8-$F8*K8) -> 0 | N8: =$D8*(1-$E8)*(J8-$F8*L8) -> 0
A9: Ni salts (cell) | B9: ='Cell & CAM'!K71 -> 0.38813452 | C9: =B48 -> 0.9 | D9: =B9*C9 -> 0.34932107 | E9: 0.2 | F9: 0.8 | G9: =$D9*(1-$E9) -> 0.27945686 | H9: Nickel Sulfate (NiSO4), GLO | K9: =_xlfn.XLOOKUP($H9,'Background data'!$D$1:$D$124,'Background data'!H$1:H$124) -> 0 | L9: =_xlfn.XLOOKUP($H9,'Background data'!$D$1:$D$124,'Background data'!J$1:J$124) -> 0 | M9: =$D9*(1-$E9)*(I9-$F9*K9) -> 0 | N9: =$D9*(1-$E9)*(J9-$F9*L9) -> 0
A10: Mn (cell) salts | B10: ='Cell & CAM'!K72 -> 0.22095769 | C10: =B49 -> 0 | D10: =B10*C10 -> 0 | E10: 0.2 | F10: 0.8 | G10: =$D10*(1-$E10) -> 0 | H10: Manganese Dioxide (MnO2) | K10: =_xlfn.XLOOKUP($H10,'Background data'!$D$1:$D$124,'Background data'!H$1:H$124) -> 0 | L10: =_xlfn.XLOOKUP($H10,'Background data'!$D$1:$D$124,'Background data'!J$1:J$124) -> 0 | M10: =$D10*(1-$E10)*(I10-$F10*K10) -> 0 | N10: =$D10*(1-$E10)*(J10-$F10*L10) -> 0
A11: Li salts (cell) | B11: ='Cell & CAM'!K73 -> 0.17030872 | C11: =B50 -> 0.5 | D11: =B11*C11 -> 0.085154361 | E11: 0.2 | F11: 0.8 | G11: =$D11*(1-$E11) -> 0.068123489 | H11: Lithium Carbonate (Li2CO3), GLO | K11: =_xlfn.XLOOKUP($H11,'Background data'!$D$1:$D$124,'Background data'!H$1:H$124) -> 0 | L11: =_xlfn.XLOOKUP($H11,'Background data'!$D$1:$D$124,'Background data'!J$1:J$124) -> 0 | M11: =$D11*(1-$E11)*(I11-$F11*K11) -> 0 | N11: =$D11*(1-$E11)*(J11-$F11*L11) -> 0
A12: Other metals and metal salts | B12: ='Cell & CAM'!K74 -> 0 | C12: =B51 -> 0 | D12: =B12*C12 -> 0 | E12: 0.2 | F12: 0.8 | G12: =$D12*(1-$E12) -> 0 | H12: Other metals and metal salts | K12: 0 | M12: =$D12*(1-$E12)*(I12-$F12*K12) -> 0 | N12: =$D12*(1-$E12)*(J12-$F12*L12) -> 0
A13: Other materials (cell) | B13: ='Cell & CAM'!K75 -> 0.59273088 | C13: =B52 -> 0 | D13: =D16-SUM(D4:D12) -> 0.31682625 | E13: 0.2 | F13: 0.8 | G13: =$D13*(1-$E13) -> 0.253461 | H13: Other materials (cell) | K13: 0 | M13: =$D13*(1-$E13)*(I13-$F13*K13) -> 0 | N13: =$D13*(1-$E13)*(J13-$F13*L13) -> 0
A14: Cell treatment - Pyrometallurgy | D14: 1 | E14: 0.2 | G14: =$D14*(1-$E14) -> 0.8 | H14: Cell treatment - Pyrometallurgy | J14: ='BOM EOL - DA'!#REF! -> #REF! | M14: =$D14*(1-$E14)*(I14-$F14*K14) -> 0 | N14: =$D14*(1-$E14)*(J14-$F14*L14) -> #REF!
A15: Cell treatment - Hydrometallurgy | D15: 1 | E15: 0.2 | G15: =$D15*(1-$E15) -> 0.8 | H15: Cell treatment - Hydrometallurgy | I15: ='BOM EOL - DA'!F$23+('BOM EOL - DA'!F$45*$B$41) -> 75.093426 | J15: =('BOM EOL - DA'!#REF!)*$B$41 -> #REF! | M15: =$D15*(1-$E15)*(I15-$F15*K15) -> 60.074741 | N15: =$D15*(1-$E15)*(J15-$F15*L15) -> #REF!
A16: TOTAL | B16: =SUM(B4:B13) -> 1.9448551 | C16: =SUMPRODUCT(B4:B13,C4:C13)/B16 -> 0.35127232 | D16: 1 | M16: =SUM(M4:M15) -> -744.56618 | N16: =SUM(N4:N15) -> #REF!
A17: return rate | B17: 0.8 | M17: =M16*$B17 -> -595.65295 | N17: =N16*$B17 -> #REF!
A19: NMC811 cell | B19: Qtté pour 1kg | C19: % recovered EoL | D19: Qtty recovered EoL | E19: A | F19: Q | G19: Qtty process | H19: Process selected | I19: Erec CO2 | J19: Erec CE | K19: Ev CO2 | L19: Ev CE | M19: crédit CO2 | N19: crédit CE
A20: Graphite / hard carbon (cell) | B20: ='Cell & CAM'!P66 -> 0.20166063 | C20: =B43 -> 0 | D20: =B20*C20 -> 0 | E20: 0.2 | F20: 0.8 | G20: =$D20*(1-$E20) -> 0 | H20: Graphite, Acheson, EI | K20: =_xlfn.XLOOKUP($H20,'Background data'!$D$1:$D$124,'Background data'!H$1:H$124) -> 0 | L20: =_xlfn.XLOOKUP($H20,'Background data'!$D$1:$D$124,'Background data'!J$1:J$124) -> 0 | M20: =$D20*(1-$E20)*(I20-$F20*K20) -> 0 | N20: =$D20*(1-$E20)*(J20-$F20*L20) -> 0
A21: Al | B21: ='Cell & CAM'!P67 -> 0.020228002 | C21: =B44 -> 0 | D21: =B21*C21 -> 0 | E21: 0.2 | F21: 1 | G21: =$D21*(1-$E21) -> 0 | H21: Aluminium, virgin, RER, Ecobalyse | K21: =_xlfn.XLOOKUP($H21,'Background data'!$D$1:$D$124,'Background data'!H$1:H$124) -> 767 | L21: =_xlfn.XLOOKUP($H21,'Background data'!$D$1:$D$124,'Background data'!J$1:J$124) -> 767 | M21: =$D21*(1-$E21)*(I21-$F21*K21) -> 0 | N21: =$D21*(1-$E21)*(J21-$F21*L21) -> 0
A22: Cu | B22: ='Cell & CAM'!P68 -> 0.12960023 | C22: =B45 -> 0.9 | D22: =B22*C22 -> 0.1166402 | E22: 0.2 | F22: 1 | G22: =$D22*(1-$E22) -> 0.093312163 | H22: Copper | K22: =_xlfn.XLOOKUP($H22,'Background data'!$D$1:$D$124,'Background data'!H$1:H$124) -> 9325 | L22: =_xlfn.XLOOKUP($H22,'Background data'!$D$1:$D$124,'Background data'!J$1:J$124) -> 9325 | M22: =$D22*(1-$E22)*(I22-$F22*K22) -> -870.13592 | N22: =$D22*(1-$E22)*(J22-$F22*L22) -> -870.13592
A23: Fe | B23: ='Cell & CAM'!P69 -> 0 | C23: =B46 -> 0 | D23: =B23*C23 -> 0 | E23: 0.2 | F23: 1 | G23: =$D23*(1-$E23) -> 0 | H23: Steel, virgin | K23: =_xlfn.XLOOKUP($H23,'Background data'!$D$1:$D$124,'Background data'!H$1:H$124) -> 111 | L23: =_xlfn.XLOOKUP($H23,'Background data'!$D$1:$D$124,'Background data'!J$1:J$124) -> 111 | M23: =$D23*(1-$E23)*(I23-$F23*K23) -> 0 | N23: =$D23*(1-$E23)*(J23-$F23*L23) -> 0
A24: Co (cell) salt | B24: ='Cell & CAM'!P70 -> 0 | C24: =B47 -> 0.9 | D24: =B24*C24 -> 0 | E24: 0.2 | F24: 0.8 | G24: =$D24*(1-$E24) -> 0 | H24: Cobalt Sulfate (CoSO4), CN | K24: =_xlfn.XLOOKUP($H24,'Background data'!$D$1:$D$124,'Background data'!H$1:H$124) -> 0 | L24: =_xlfn.XLOOKUP($H24,'Background data'!$D$1:$D$124,'Background data'!J$1:J$124) -> 0 | M24: =$D24*(1-$E24)*(I24-$F24*K24) -> 0 | N24: =$D24*(1-$E24)*(J24-$F24*L24) -> 0
A25: Ni salts (cell) | B25: ='Cell & CAM'!P71 -> 0 | C25: =B48 -> 0.9 | D25: =B25*C25 -> 0 | E25: 0.2 | F25: 0.8 | G25: =$D25*(1-$E25) -> 0 | H25: Nickel Sulfate (NiSO4), GLO | K25: =_xlfn.XLOOKUP($H25,'Background data'!$D$1:$D$124,'Background data'!H$1:H$124) -> 0 | L25: =_xlfn.XLOOKUP($H25,'Background data'!$D$1:$D$124,'Background data'!J$1:J$124) -> 0 | M25: =$D25*(1-$E25)*(I25-$F25*K25) -> 0 | N25: =$D25*(1-$E25)*(J25-$F25*L25) -> 0
A26: Mn (cell) salts | B26: ='Cell & CAM'!P72 -> 0 | C26: =B49 -> 0 | D26: =B26*C26 -> 0 | E26: 0.2 | F26: 0.8 | G26: =$D26*(1-$E26) -> 0 | H26: Manganese Dioxide (MnO2) | K26: =_xlfn.XLOOKUP($H26,'Background data'!$D$1:$D$124,'Background data'!H$1:H$124) -> 0 | L26: =_xlfn.XLOOKUP($H26,'Background data'!$D$1:$D$124,'Background data'!J$1:J$124) -> 0 | M26: =$D26*(1-$E26)*(I26-$F26*K26) -> 0 | N26: =$D26*(1-$E26)*(J26-$F26*L26) -> 0
A27: Li salts (cell) | B27: ='Cell & CAM'!P73 -> 0.1041033 | C27: =B50 -> 0.5 | D27: =B27*C27 -> 0.052051648 | E27: 0.2 | F27: 0.8 | G27: =$D27*(1-$E27) -> 0.041641318 | H27: Lithium Carbonate (Li2CO3), GLO | K27: =_xlfn.XLOOKUP($H27,'Background data'!$D$1:$D$124,'Background data'!H$1:H$124) -> 0 | L27: =_xlfn.XLOOKUP($H27,'Background data'!$D$1:$D$124,'Background data'!J$1:J$124) -> 0 | M27: =$D27*(1-$E27)*(I27-$F27*K27) -> 0 | N27: =$D27*(1-$E27)*(J27-$F27*L27) -> 0
A28: Other metals and metal salts | B28: ='Cell & CAM'!P74 -> 0 | C28: =B51 -> 0 | D28: =B28*C28 -> 0 | E28: 0.2 | F28: 0.8 | G28: =$D28*(1-$E28) -> 0 | H28: Other metals and metal salts | K28: 0 | M28: =$D28*(1-$E28)*(I28-$F28*K28) -> 0 | N28: =$D28*(1-$E28)*(J28-$F28*L28) -> 0
A29: Other materials (cell) | B29: ='Cell & CAM'!P75 -> 0.58743995 | C29: =B52 -> 0 | D29: =D32-SUM(D20:D28) -> 0.83130815 | E29: 0.2 | F29: 0.8 | G29: =$D29*(1-$E29) -> 0.66504652 | H29: Other materials (cell) | K29: 0 | M29: =$D29*(1-$E29)*(I29-$F29*K29) -> 0 | N29: =$D29*(1-$E29)*(J29-$F29*L29) -> 0
A30: Cell treatment - Pyrometallurgy | D30: 1 | E30: 0.2 | G30: =$D30*(1-$E30) -> 0.8 | H30: Cell treatment - Pyrometallurgy | J30: ='BOM EOL - DA'!#REF! -> #REF! | M30: =$D30*(1-$E30)*(I30-$F30*K30) -> 0 | N30: =$D30*(1-$E30)*(J30-$F30*L30) -> #REF!
A31: Cell treatment - Hydrometallurgy | D31: 1 | E31: 0.2 | G31: =$D31*(1-$E31) -> 0.8 | H31: Cell treatment - Hydrometallurgy | I31: ='BOM EOL - DA'!F$23+('BOM EOL - DA'!F$45*$B$41) -> 75.093426 | J31: =('BOM EOL - DA'!#REF!)*$B$41 -> #REF! | M31: =$D31*(1-$E31)*(I31-$F31*K31) -> 60.074741 | N31: =$D31*(1-$E31)*(J31-$F31*L31) -> #REF!
A32: TOTAL | B32: =SUM(B20:B29) -> 1.0430321 | C32: =SUMPRODUCT(B20:B29,C20:C29)/B32 -> 0.16173218 | D32: 1 | G32: =$D32*(1-$E32) -> 1 | M32: =SUM(M20:M31) -> -810.06118 | N32: =SUM(N20:N31) -> #REF!
A33: return rate | B33: 0.8 | M33: =M32*$B33 -> -648.04894 | N33: =N32*$B33 -> #REF!
B38: Retenu
B39: =_xlfn.XLOOKUP($B$1,$C$39:$E$39,C39:E39) -> Reglement batterie obj. 2027 | C39: Acte Délégué | D39: Reglement batterie obj. 2027 | E39: Reglement batterie ob. 2031
A40: Quantité procédé hydro DA | B40: =_xlfn.XLOOKUP($B$1,$C$39:$E$39,C40:E40) -> Métaux + slag | C40: Métaux seul | D40: Métaux + slag | E40: Métaux + slag
A41: Quantité procédé hydro DA | B41: =_xlfn.XLOOKUP($B$1,$C$39:$E$39,C41:E41) -> 2.9411765 | C41: 1 | D41: =1/0.34 -> 2.9411765 | E41: =1/0.34 -> 2.9411765
A42: Part récupérée
A43: Graphite / hard carbon (cell) | B43: =_xlfn.XLOOKUP($B$1,$C$39:$E$39,C43:E43) -> 0 | C43: 0 | D43: 0 | E43: 0
A44: Al | B44: =_xlfn.XLOOKUP($B$1,$C$39:$E$39,C44:E44) -> 0 | C44: 0 | D44: 0 | E44: 0
A45: Cu | B45: =_xlfn.XLOOKUP($B$1,$C$39:$E$39,C45:E45) -> 0.9 | C45: 0.9 | D45: 0.9 | E45: 0.95
A46: Fe | B46: =_xlfn.XLOOKUP($B$1,$C$39:$E$39,C46:E46) -> 0 | C46: 0 | D46: 0 | E46: 0
...

Sheet BOM EOL - DA
A1: 1/ Battery cell recycling process per kg of battery cell : pyrometallurgical step
A2: Source données | B2: Acte délégué Article 7 Battery regulation - Table 4
A4: Inputs
A5: Component | B5: description | C5: Unit | D5: default value | E5: Modelling | F5: ='Background data'!$B$1 -> ECS EI3.9.1 (Pts)
A6: End of life battery cells | B6: from disassembly | C6: kg | D6: 1
A7: Electricity | B7: Electricity mix, RER | C7: kWh | D7: 1 | E7: Electricity mix, RER | F7: =$D7*_xlfn.XLOOKUP($E7,'Background data'!$D:$D,'Background data'!H:H) -> 25.72
A8: process heat | B8: Heat, from natural gas, Europe | C8: MJ | D8: =2.288 -> 2.288 | E8: Heat, from natural gas, Europe | F8: =$D8*_xlfn.XLOOKUP($E8,'Background data'!$D:$D,'Background data'!H:H) -> 0
A9: process heat | B9: Heat from diesel fuel, Europe | C9: MJ | D9: =0.237 -> 0.237 | E9: Heat from diesel fuel, Europe | F9: =$D9*_xlfn.XLOOKUP($E9,'Background data'!$D:$D,'Background data'!H:H) -> 0
A10: limestone washed | B10: Limestone production, technology mix | C10: kg | D10: 0.136 | E10: Limestone | F10: =$D10*_xlfn.XLOOKUP($E10,'Background data'!$D:$D,'Background data'!H:H) -> 0
A11: Silica sand | B11: Silica sand, production mix | C11: kg | D11: 0.119 | E11: Silica sand | F11: =$D11*_xlfn.XLOOKUP($E11,'Background data'!$D:$D,'Background data'!H:H) -> 0
A12: Quicklime (CAO) | B12: Quicklime production, technology mix | C12: kg | D12: 0.085 | E12: Quicklime | F12: =$D12*_xlfn.XLOOKUP($E12,'Background data'!$D:$D,'Background data'!H:H) -> 0
A13: Carbon black | B13: Carbon black production, technology mix | C13: kg | D13: 0.001 | E13: Carbon black | F13: =$D13*_xlfn.XLOOKUP($E13,'Background data'!$D:$D,'Background data'!H:H) -> 0
A14: Transport from the dissembling to the battery cell recycling plant | B14: Transport by truck (>32 t, EURO 4); | C14: t.km | D14: 0.13 | E14: Transport, truck (>32 t, EURO 4); | F14: =$D14*_xlfn.XLOOKUP($E14,'Background data'!$D:$D,'Background data'!H:H) -> 1.1934
A15: Transport from the dissembling to the battery cell recycling plant | B15: Transport by train (average freight train) | C15: t.km | D15: 0.24 | E15: Transport, train | F15: =$D15*_xlfn.XLOOKUP($E15,'Background data'!$D:$D,'Background data'!H:H) -> 1.044
A16: Transport from the dissembling to the battery cell recycling plantf | B16: Transport by ship (barge). | C16: t.km | D16: 0.27 | E16: Transport, ship (barge). | F16: =$D16*_xlfn.XLOOKUP($E16,'Background data'!$D:$D,'Background data'!H:H) -> 1.1988
A18: Outputs
A19: Metal alloy | B19: To hydrometallurgical tretment | C19: kg | D19: 0.209
A20: Slag | B20: Landfill of inert slag | C20: kg | D20: 0.712 | E20: Landfill of inert slag | F20: 0
A21: Emissions | B21: Direct process emissions (all greenhouse gases) | C21: kgCO2eq. | D21: 1.194 | E21: Direct process GHG emissions | F21: =$D21*_xlfn.XLOOKUP($E21,'Background data'!$D:$D,'Background data'!H:H) -> 33.3126
A23: TOTAL IMPACT Erec | F23: =SUM(F7:F21) -> 62.4688
A25: 2/ Default values for battery cell recycling process per kg of battery cell: hydrometallurgical treatment.
A26: Source données | B26: Acte délégué Article 7 Battery regulation - Table 5
A28: Inputs
A29: Component | B29: description | C29: Unit | D29: default value | E29: Modelling | F29: ='Background data'!$B$1 -> ECS EI3.9.1 (Pts)
A30: Metal alloy | B30: To hydrometallurgical treatment | C30: kg | D30: 0.34
A31: Electricity | B31: Electricity mix, RER | C31: kWh | D31: 0.085 | E31: Electricity mix, RER | F31: =$D31*_xlfn.XLOOKUP($E31,'Background data'!$D:$D,'Background data'!H:H) -> 2.1862
A32: Process heat | B32: Heat, from natural gas, Europe | C32: kWh | D32: =1.847 -> 1.847 | E32: Heat, from natural gas, Europe | F32: =$D32*_xlfn.XLOOKUP($E32,'Background data'!$D:$D,'Background data'!H:H) -> 0
A33: Hydrochloric acid (100%) | B33: HCl production, technology mix | C33: kg | D33: 0.017 | E33: Hydrochloric Acid (HCl) | F33: =$D33*_xlfn.XLOOKUP($E33,'Background data'!$D:$D,'Background data'!H:H) -> 0
A34: Hydrogen peroxide (100%) | B34: Hydrogen peroxide, production, technology mix | C34: kg | D34: 0.305 | E34: Hydrogen peroxide | F34: =$D34*_xlfn.XLOOKUP($E34,'Background data'!$D:$D,'Background data'!H:H) -> 0
A35: Soda (sodium carbonate) | B35: Soda production, technology mix | C35: kg | D35: 0.017 | E35: Soda | F35: =$D35*_xlfn.XLOOKUP($E35,'Background data'!$D:$D,'Background data'!H:H) -> 0
A36: Sodium hydroxide (100%; caustic soda) | B36: Sodium hydroxide production, technology mix | C36: kg | D36: 0.458 | E36: Sodium Hydroxide (NaOH), GLO | F36: =$D36*_xlfn.XLOOKUP($E36,'Background data'!$D:$D,'Background data'!H:H) -> 0
A37: Sulphuric acid aq. (96%) | B37: Sulphuric acid production, technology mix | C37: kg | D37: 0.881 | E37: Sulfuric acid (H2SO4) | F37: =$D37*_xlfn.XLOOKUP($E37,'Background data'!$D:$D,'Background data'!H:H) -> 0
A38: Water (tap water) | B38: Water (tap water) | C38: kg | D38: 3 | E38: Water (tap water) | F38: =$D38*_xlfn.XLOOKUP($E38,'Background data'!$D:$D,'Background data'!H:H) -> 0.81
A40: Outputs
A41: Recovered metals | B41: Such as aluminium, copper, steel and stainless steel | C41: kg
A42: Recovered metal salts | B42: Such as cobalt sulphate and nickel sulphate | C42: kg
A43: Wastewater | B43: Wastewater treatment, average | C43: m3 | D43: 0.00864 | E43: Wastewater treatment, average | F43: =$D43*_xlfn.XLOOKUP($E43,'Background data'!$D:$D,'Background data'!H:H) -> 1.2961728
A45: TOTAL IMPACT Erec | F45: =SUM(F30:F43) -> 4.2923728

Sheet Background data
A1: Background data | B1: ECS EI3.9.1 (Pts) | F1: Data hidden pour licence limitation | G1: Data to be completed by Ecobalyse
H2: Retenu
A3: Name, EN | B3: Name, FR | C3: Details, Geography | D3: Reference | E3: unit | F3: EI LCI dataset (or based on EI) | G3: BAFU LCI dataset (or based on BAFU) | H3: =$B$1 -> ECS EI3.9.1 (Pts) | I3: GWP EI3.11 (kgCO2eq) | J3: ECS EI3.9.1 (Pts) | K3: GWP BAFU2 (kgCO2eq) | L3: ECS BAFU3 (Pts)
A4: Cells
A5: Cells, LFP Hydro | C5: CN, Ecobalyse | D5: =IF(ISBLANK(C5),A5,A5&", "&C5) -> Cells, LFP Hydro, CN, Ecobalyse | E5: kg | F5: Battery cell production, LFP Hydrothermal, CN | H5: =_xlfn.XLOOKUP($B$1,$I$3:$L$3,$I5:$L5,,0) -> 4478 | J5: 4478
A6: Cells, LFP Solid | C6: CN, Ecobalyse | D6: =IF(ISBLANK(C6),A6,A6&", "&C6) -> Cells, LFP Solid, CN, Ecobalyse | E6: kg | F6: Battery cell production, LFP Solid State, CN | H6: =_xlfn.XLOOKUP($B$1,$I$3:$L$3,$I6:$L6,,0) -> 4189 | J6: 4189
A7: Cells, NMC811 | C7: CN, Ecobalyse | D7: =IF(ISBLANK(C7),A7,A7&", "&C7) -> Cells, NMC811, CN, Ecobalyse | E7: kg | F7: Battery cell production, NMC811, CN | H7: =_xlfn.XLOOKUP($B$1,$I$3:$L$3,$I7:$L7,,0) -> 6661 | J7: 6661
A8: Cells, NMC811 | C8: FR, Ecobalyse | D8: =IF(ISBLANK(C8),A8,A8&", "&C8) -> Cells, NMC811, FR, Ecobalyse | E8: kg | F8: Battery cell production, NMC811, FR | H8: =_xlfn.XLOOKUP($B$1,$I$3:$L$3,$I8:$L8,,0) -> 5446 | J8: 5446
A9: Cells, NMC622 | C9: CN, Ecobalyse | D9: =IF(ISBLANK(C9),A9,A9&", "&C9) -> Cells, NMC622, CN, Ecobalyse | E9: kg | F9: Battery cell production, LFP Hydrothermal, CN | H9: =_xlfn.XLOOKUP($B$1,$I$3:$L$3,$I9:$L9,,0) -> 5446 | J9: 5446
A11: Casing, steel
A12: Steel, virgin | B12: Acier vierge | D12: =IF(ISBLANK(C12),A12,A12&", "&C12) -> Steel, virgin | E12: kg | F12: steel, unalloyed//[RER] steel production, converter, unalloyed | G12: Steel, converter, low-alloyed, at plant {RER} | H12: =_xlfn.XLOOKUP($B$1,$I$3:$L$3,$I12:$L12,,0) -> 111 | J12: 111 | K12: 2.409987
A13: Steel, market mix | B13: Acier mix marché (Europe) | D13: =IF(ISBLANK(C13),A13,A13&", "&C13) -> Steel, market mix | E13: kg | F13: steel, low-alloyed, market, FR, constructed by Ecobalyse | H13: =_xlfn.XLOOKUP($B$1,$I$3:$L$3,$I13:$L13,,0) -> 90.297396 | J13: 90.297396
A14: Steel, market mix | B14: Acier mix marché (Reste du monde) | D14: =IF(ISBLANK(C14),A14,A14&", "&C14) -> Steel, market mix | E14: kg | F14: steel, low-alloyed, market, CN, constructed by Ecobalyse | H14: =_xlfn.XLOOKUP($B$1,$I$3:$L$3,$I14:$L14,,0) -> 116.10143 | J14: 116.10143
A15: Chromium steel | B15: Acier inoxydable | D15: =IF(ISBLANK(C15),A15,A15&", "&C15) -> Chromium steel | E15: kg | F15: steel, chromium steel 18/8//[GLO] market for steel, chromium steel 18/8 | H15: =_xlfn.XLOOKUP($B$1,$I$3:$L$3,$I15:$L15,,0) -> 470.32639 | J15: 470.32639
A16: Lamination (acier) | B16: Lamination (acier) | D16: =IF(ISBLANK(C16),A16,A16&", "&C16) -> Lamination (acier) | E16: kg | F16: steel sheet rolling, constructed by Ecobalyse | H16: =_xlfn.XLOOKUP($B$1,$I$3:$L$3,$I16:$L16,,0) -> 13.316606 | J16: 13.316606
A17: Lamination (inox) | B17: Lamination (inox) | D17: =IF(ISBLANK(C17),A17,A17&", "&C17) -> Lamination (inox) | E17: kg | F17: chromium steel sheet rolling, constructed by Ecobalyse | H17: =_xlfn.XLOOKUP($B$1,$I$3:$L$3,$I17:$L17,,0) -> 33.166921 | J17: 33.166921
A19: Casing, Aluminium
A20: Aluminium, virgin | B20: Aluminium vierge | C20: RER, Ecobalyse | D20: =IF(ISBLANK(C20),A20,A20&", "&C20) -> Aluminium, virgin, RER, Ecobalyse | E20: kg | F20: aluminium ingot, virgin, market, RER | G20: Aluminium, primary, at plant {RER} | H20: =_xlfn.XLOOKUP($B$1,$I$3:$L$3,$I20:$L20,,0) -> 767 | J20: 767 | K20: 8.9122263
A21: Aluminium, market mix | B21: Aluminium mix marché | C21: CN, Ecobalyse | D21: =IF(ISBLANK(C21),A21,A21&", "&C21) -> Aluminium, market mix, CN, Ecobalyse | E21: kg | F21: aluminium, low-alloyed, virgin, market, CN, constructed by Ecobalyse | H21: =_xlfn.XLOOKUP($B$1,$I$3:$L$3,$I21:$L21,,0) -> 1503.0263 | J21: 1503.0263
A22: Aluminium, market mix | B22: Aluminium mix marché | C22: RER, Ecobalyse | D22: =IF(ISBLANK(C22),A22,A22&", "&C22) -> Aluminium, market mix, RER, Ecobalyse | E22: kg | F22: aluminium, low-alloyed, market, RER, constructed by Ecobalyse | H22: =_xlfn.XLOOKUP($B$1,$I$3:$L$3,$I22:$L22,,0) -> 539.64118 | J22: 539.64118
A23: Aluminium, market mix | B23: Aluminium mix marché | C23: RoW, Ecobalyse | D23: =IF(ISBLANK(C23),A23,A23&", "&C23) -> Aluminium, market mix, RoW, Ecobalyse | E23: kg | F23: aluminium, low-alloyed, market, RoW, constructed by Ecobalyse | H23: =_xlfn.XLOOKUP($B$1,$I$3:$L$3,$I23:$L23,,0) -> 893.80654 | J23: 893.80654
A24: Lamination (aluminium) | B24: Lamination (aluminium) | D24: =IF(ISBLANK(C24),A24,A24&", "&C24) -> Lamination (aluminium) | E24: kg | F24: Aluminium sheeet rolling, constructed by Ecobalyse | H24: =_xlfn.XLOOKUP($B$1,$I$3:$L$3,$I24:$L24,,0) -> 21.538888 | J24: 21.538888
A25: Extrusion (aluminium) | B25: Extrusion (aluminium) | D25: =IF(ISBLANK(C25),A25,A25&", "&C25) -> Extrusion (aluminium) | E25: kg | F25: Aluminium extrusion, constructed by Ecobalyse | H25: =_xlfn.XLOOKUP($B$1,$I$3:$L$3,$I25:$L25,,0) -> 44.464254 | J25: 44.464254
A27: Casing, Plastics
A28: Plastique granulé (PET) | B28: Plastique granulé (PET) | D28: =IF(ISBLANK(C28),A28,A28&", "&C28) -> Plastique granulé (PET) | E28: kg | F28: polyethylene terephthalate, granulate, amorphous//[GLO] market for polyethylene terephthalate, granulate, amorphous | G28: Polyethylene terephthalate, granulate, amorphous, at plant {RER} | H28: =_xlfn.XLOOKUP($B$1,$I$3:$L$3,$I28:$L28,,0) -> 281.47193 | J28: 281.47193 | K28: 2.8007527
A29: Plastique granulé (PVC) | B29: Plastique granulé (PVC) | D29: =IF(ISBLANK(C29),A29,A29&", "&C29) -> Plastique granulé (PVC) | E29: kg | F29: polyvinylchloride, suspension polymerised//[GLO] market for polyvinylchloride, suspension polymerised | H29: =_xlfn.XLOOKUP($B$1,$I$3:$L$3,$I29:$L29,,0) -> 207.6437 | J29: 207.6437 | K29: 0
A30: Plastique granulé (divers) | B30: Plastique granulé (divers) | D30: =IF(ISBLANK(C30),A30,A30&", "&C30) -> Plastique granulé (divers) | E30: kg | F30: polypropylene, granulate//[GLO] market for polypropylene, granulate | G30: Polypropylene, granulate, at plant {RER} | H30: =_xlfn.XLOOKUP($B$1,$I$3:$L$3,$I30:$L30,,0) -> 196.58178 | J30: 196.58178 | K30: 2.1040782
